Workbook

Sheet summery 
B4: SPUR WISE STACKING
D5: =IF(SUM(D6:D17)>2,1,0) -> 0 | E5: =IF(SUM(E6:E17)>2,1,0) -> 1 | F5: =IF(SUM(F6:F17)>2,1,0) -> 0 | G5: =IF(SUM(G6:G17)>2,1,0) -> 0 | H5: =IF(SUM(H6:H17)>2,1,0) -> 0 | I5: =IF(SUM(I6:I17)>2,1,0) -> 0 | J5: =IF(SUM(J6:J17)>2,1,0) -> 1 | K5: =IF(SUM(K6:K17)>2,1,0) -> 0 | ... S5: =IF(SUM(S6:S17)>2,1,0) -> 0
B6: SPUR 1 | D6: ='PILE-1A'!L23 -> 0 | E6: ='PILE-1B'!L23 -> 1 | F6: ='PILE-1C'!L23 -> 0 | G6: ='PILE-1D'!L19 -> 0 | H6: ='PILE-2A'!L23 -> 1 | I6: ='PILE-2B'!L23 -> 0 | J6: ='PILE-2C'!L23 -> 1 | K6: ='PILE-2D'!L23 -> 0 | L6: ='PILE-3A'!L20 -> 0 | M6: ='PILE-3B'!L23 -> 0 | N6: ='PILE-3C'!L23 -> 0 | O6: ='PILE-3D'!L21 -> 0 | P6: ='PILE-4A'!L23 -> 1 | Q6: ='PILE-4B'!L22 -> 0 | R6: ='PILE-4C'!L19 -> 1 | S6: ='PILE-4D'!L23 -> 0
B7: SPUR 2 | D7: ='PILE-1A'!L24 -> 1 | E7: ='PILE-1B'!L24 -> 0 | F7: ='PILE-1C'!L24 -> 0 | G7: ='PILE-1D'!L20 -> 0 | H7: ='PILE-2A'!L24 -> 0 | I7: ='PILE-2B'!L24 -> 0 | J7: ='PILE-2C'!L24 -> 1 | K7: ='PILE-2D'!L24 -> 0 | L7: ='PILE-3A'!L21 -> 1 | M7: ='PILE-3B'!L24 -> 0 | N7: ='PILE-3C'!L24 -> 0 | O7: ='PILE-3D'!L22 -> 0 | P7: ='PILE-4A'!L24 -> 0 | Q7: ='PILE-4B'!L23 -> 0 | R7: ='PILE-4C'!L20 -> 1 | S7: ='PILE-4D'!L24 -> 0
B8: SPUR 3 | D8: ='PILE-1A'!L25 -> 0 | E8: ='PILE-1B'!L25 -> 0 | F8: ='PILE-1C'!L25 -> 0 | G8: ='PILE-1D'!L21 -> 0 | H8: ='PILE-2A'!L25 -> 0 | I8: ='PILE-2B'!L25 -> 0 | J8: ='PILE-2C'!L25 -> 0 | K8: ='PILE-2D'!L25 -> 0 | L8: ='PILE-3A'!L22 -> 1 | M8: ='PILE-3B'!L25 -> 0 | N8: ='PILE-3C'!L25 -> 0 | O8: ='PILE-3D'!L23 -> 0 | P8: ='PILE-4A'!L25 -> 1 | Q8: ='PILE-4B'!L24 -> 0 | R8: ='PILE-4C'!L21 -> 0 | S8: ='PILE-4D'!L25 -> 0
B9: SPUR 4 | D9: ='PILE-1A'!L26 -> 0 | E9: ='PILE-1B'!L26 -> 0 | F9: ='PILE-1C'!L26 -> 0 | G9: ='PILE-1D'!L22 -> 0 | H9: ='PILE-2A'!L26 -> 0 | I9: ='PILE-2B'!L26 -> 0 | J9: ='PILE-2C'!L26 -> 1 | K9: ='PILE-2D'!L26 -> 0 | L9: ='PILE-3A'!L23 -> 0 | M9: ='PILE-3B'!L26 -> 0 | N9: ='PILE-3C'!L26 -> 0 | O9: ='PILE-3D'!L24 -> 1 | P9: ='PILE-4A'!L26 -> 1 | Q9: ='PILE-4B'!L25 -> 0 | R9: ='PILE-4C'!L22 -> 0 | S9: ='PILE-4D'!L26 -> 0
B10: SPUR 5 | D10: ='PILE-1A'!L27 -> 0 | E10: ='PILE-1B'!L27 -> 1 | F10: ='PILE-1C'!L27 -> 0 | G10: ='PILE-1D'!L23 -> 0 | H10: ='PILE-2A'!L27 -> 0 | I10: ='PILE-2B'!L27 -> 0 | J10: ='PILE-2C'!L27 -> 0 | K10: ='PILE-2D'!L27 -> 1 | L10: ='PILE-3A'!L24 -> 0 | M10: ='PILE-3B'!L27 -> 1 | N10: ='PILE-3C'!L27 -> 0 | O10: ='PILE-3D'!L25 -> 0 | P10: ='PILE-4A'!L27 -> 1 | Q10: ='PILE-4B'!L26 -> 0 | R10: ='PILE-4C'!L23 -> 0 | S10: ='PILE-4D'!L27 -> 1
B11: SPUR 6 | D11: ='PILE-1A'!L28 -> 0 | E11: ='PILE-1B'!L28 -> 0 | F11: ='PILE-1C'!L28 -> 0 | G11: ='PILE-1D'!L24 -> 0 | H11: ='PILE-2A'!L28 -> 0 | I11: ='PILE-2B'!L28 -> 1 | J11: ='PILE-2C'!L28 -> 1 | K11: ='PILE-2D'!L28 -> 0 | L11: ='PILE-3A'!L25 -> 0 | M11: ='PILE-3B'!L28 -> 0 | N11: ='PILE-3C'!L28 -> 0 | O11: ='PILE-3D'!L26 -> 1 | P11: ='PILE-4A'!L28 -> 0 | Q11: ='PILE-4B'!L27 -> 1 | R11: ='PILE-4C'!L24 -> 0 | S11: ='PILE-4D'!L28 -> 0
B12: SPUR 7 | D12: ='PILE-1A'!L29 -> 0 | E12: ='PILE-1B'!L29 -> 0 | F12: ='PILE-1C'!L29 -> 0 | G12: ='PILE-1D'!L25 -> 0 | H12: ='PILE-2A'!L29 -> 0 | I12: ='PILE-2B'!L29 -> 0 | J12: ='PILE-2C'!L29 -> 0 | K12: ='PILE-2D'!L29 -> 0 | L12: ='PILE-3A'!L26 -> 0 | M12: ='PILE-3B'!L29 -> 0 | N12: ='PILE-3C'!L29 -> 0 | O12: ='PILE-3D'!L27 -> 0 | P12: ='PILE-4A'!L29 -> 0 | Q12: ='PILE-4B'!L28 -> 0 | R12: ='PILE-4C'!L25 -> 0 | S12: ='PILE-4D'!L29 -> 0
B13: SPUR 8 | D13: ='PILE-1A'!L30 -> 0 | E13: ='PILE-1B'!L30 -> 0 | F13: ='PILE-1C'!L30 -> 0 | G13: ='PILE-1D'!L26 -> 0 | H13: ='PILE-2A'!L30 -> 0 | I13: ='PILE-2B'!L30 -> 0 | J13: ='PILE-2C'!L30 -> 0 | K13: ='PILE-2D'!L30 -> 0 | L13: ='PILE-3A'!L27 -> 0 | M13: ='PILE-3B'!L30 -> 0 | N13: ='PILE-3C'!L30 -> 1 | O13: ='PILE-3D'!L28 -> 0 | P13: ='PILE-4A'!L30 -> 0 | Q13: ='PILE-4B'!L29 -> 0 | R13: ='PILE-4C'!L26 -> 0 | S13: ='PILE-4D'!L30 -> 1
B14: SPUR 9 | D14: ='PILE-1A'!L31 -> 0 | E14: ='PILE-1B'!L31 -> 1 | F14: ='PILE-1C'!L31 -> 0 | G14: ='PILE-1D'!L27 -> 0 | H14: ='PILE-2A'!L31 -> 0 | I14: ='PILE-2B'!L31 -> 0 | J14: ='PILE-2C'!L31 -> 0 | K14: ='PILE-2D'!L31 -> 0 | L14: ='PILE-3A'!L28 -> 0 | M14: ='PILE-3B'!L31 -> 0 | N14: ='PILE-3C'!L31 -> 0 | O14: ='PILE-3D'!L29 -> 0 | P14: ='PILE-4A'!L31 -> 0 | Q14: ='PILE-4B'!L30 -> 0 | R14: ='PILE-4C'!L27 -> 0 | S14: ='PILE-4D'!L31 -> 0
B15: SPUR 10 | D15: ='PILE-1A'!L32 -> 0 | E15: ='PILE-1B'!L32 -> 1 | F15: ='PILE-1C'!L32 -> 0 | G15: ='PILE-1D'!L28 -> 0 | H15: ='PILE-2A'!L32 -> 0 | I15: ='PILE-2B'!L32 -> 0 | J15: ='PILE-2C'!L32 -> 0 | K15: ='PILE-2D'!L32 -> 0 | L15: ='PILE-3A'!L29 -> 0 | M15: ='PILE-3B'!L32 -> 0 | N15: ='PILE-3C'!L32 -> 0 | O15: ='PILE-3D'!L30 -> 0 | P15: ='PILE-4A'!L32 -> 0 | Q15: ='PILE-4B'!L31 -> 0 | R15: ='PILE-4C'!L28 -> 0 | S15: ='PILE-4D'!L32 -> 0
B16: SILO | D16: ='PILE-1A'!L33 -> 1 | E16: ='PILE-1B'!L33 -> 0 | F16: ='PILE-1C'!L33 -> 1 | G16: ='PILE-1D'!L29 -> 0 | H16: ='PILE-2A'!L33 -> 0 | I16: ='PILE-2B'!L33 -> 1 | J16: ='PILE-2C'!L33 -> 0 | K16: ='PILE-2D'!L33 -> 0 | L16: ='PILE-3A'!L30 -> 1 | M16: ='PILE-3B'!L33 -> 0 | N16: ='PILE-3C'!L33 -> 1 | O16: ='PILE-3D'!L31 -> 0 | P16: ='PILE-4A'!L33 -> 1 | Q16: ='PILE-4B'!L32 -> 0 | R16: ='PILE-4C'!L29 -> 0 | S16: ='PILE-4D'!L33 -> 0
B17: DB | D17: ='PILE-1A'!L34 -> 0 | E17: ='PILE-1B'!L34 -> 0 | F17: ='PILE-1C'!L34 -> 0 | G17: ='PILE-1D'!L30 -> 0 | H17: ='PILE-2A'!L34 -> 0 | I17: ='PILE-2B'!L34 -> 0 | J17: ='PILE-2C'!L34 -> 0 | K17: ='PILE-2D'!L34 -> 0 | L17: ='PILE-3A'!L31 -> 0 | M17: ='PILE-3B'!L34 -> 0 | N17: ='PILE-3C'!L34 -> 0 | O17: ='PILE-3D'!L32 -> 0 | P17: ='PILE-4A'!L34 -> 0 | Q17: ='PILE-4B'!L33 -> 0 | R17: ='PILE-4C'!L30 -> 0 | S17: ='PILE-4D'!L34 -> 0
B18: COAL QUANTITY AND QUALITY PILEWISE
B19: PILE | C19: Total | D19: 1A | E19: 1B | F19: 1C | G19: 1D | H19: 2A | I19: 2B | J19: 2C | K19: 2D | L19: 3A | M19: 3B | N19: 3C | O19: 3D | P19: 4A | Q19: 4B | R19: 4C | S19: 4D | T19: WT | U19: total
B20: ='PILE-1A'!J23 -> AVILABLE QUANITY | C20: =U20 -> 283495 | D20: =IFERROR('PILE-1A'!K23,"0") -> 21285 | E20: =IFERROR('PILE-1B'!K23,"0") -> 29383 | F20: =IFERROR('PILE-1C'!K23,"0") -> 17196 | G20: =IFERROR('PILE-1D'!K19,"0") -> 25426 | H20: =IFERROR('PILE-2A'!K23,"0") -> 7950 | I20: =IFERROR('PILE-2B'!K23,"0") -> 8405 | J20: =IFERROR('PILE-2C'!K23,"0") -> 25269 | K20: =IFERROR('PILE-2D'!K23,"0") -> 7506 | L20: =IFERROR('PILE-3A'!K20,"0") -> 10277 | M20: =IFERROR('PILE-3B'!K23,"0") -> 10408 | N20: =IFERROR('PILE-3C'!K23,"0") -> 12014 | O20: =IFERROR('PILE-3D'!K21,"0") -> 21625 | P20: =IFERROR('PILE-4A'!K23,"0") -> 21474 | Q20: =IFERROR('PILE-4B'!K22,"0") -> 17640 | R20: =IFERROR('PILE-4C'!K19,"0") -> 20399 | S20: =IFERROR('PILE-4D'!K23,"0") -> 19238 | T20: 8000 | U20: =SUM(D20:T20) -> 283495
B21: ='PILE-1A'!J24 -> PILE WTD GCV | C21: =U21 -> 3258.9516 | D21: =IFERROR('PILE-1A'!K24,"0") -> 3272.715 | E21: =IFERROR('PILE-1B'!K24,"0") -> 2972.2111 | F21: =IFERROR('PILE-1C'!K24,"0") -> 3520.836 | G21: =IFERROR('PILE-1D'!K20,"0") -> 3465.2719 | H21: =IFERROR('PILE-2A'!K24,"0") -> 2654.5665 | I21: =IFERROR('PILE-2B'!K24,"0") -> 3317.6894 | J21: =IFERROR('PILE-2C'!K24,"0") -> 3196.7346 | K21: =IFERROR('PILE-2D'!K24,"0") -> 3637 | L21: =IFERROR('PILE-3A'!K21,"0") -> 3090.8703 | M21: =IFERROR('PILE-3B'!K24,"0") -> 3066.3381 | N21: =IFERROR('PILE-3C'!K24,"0") -> 3102.4667 | O21: =IFERROR('PILE-3D'!K22,"0") -> 3249.6039 | P21: =IFERROR('PILE-4A'!K24,"0") -> 3146.0397 | Q21: =IFERROR('PILE-4B'!K23,"0") -> 3439.3415 | R21: =IFERROR('PILE-4C'!K20,"0") -> 3507.6797 | S21: =IFERROR('PILE-4D'!K24,"0") -> 3356.8523 | T21: 3200 | U21: =SUMPRODUCT(D20:T20,D21:T21)/U20 -> 3258.9516
B22: ='PILE-1A'!J25 -> TOP GCV | C22: =U22 -> 3296.1906 | D22: =IFERROR('PILE-1A'!K25,"0") -> 3409.9234 | E22: =IFERROR('PILE-1B'!K25,"0") -> 3042.5866 | F22: =IFERROR('PILE-1C'!K25,"0") -> 3501.7591 | G22: =IFERROR('PILE-1D'!K21,"0") -> 3528.6696 | H22: =IFERROR('PILE-2A'!K25,"0") -> 0 | I22: =IFERROR('PILE-2B'!K25,"0") -> 0 | J22: =IFERROR('PILE-2C'!K25,"0") -> 3323.8239 | K22: =IFERROR('PILE-2D'!K25,"0") -> 0 | L22: =IFERROR('PILE-3A'!K22,"0") -> 0 | M22: =IFERROR('PILE-3B'!K25,"0") -> 3173 | N22: =IFERROR('PILE-3C'!K25,"0") -> 3153 | O22: =IFERROR('PILE-3D'!K23,"0") -> 3301.3502 | P22: =IFERROR('PILE-4A'!K25,"0") -> 3079.3618 | Q22: =IFERROR('PILE-4B'!K24,"0") -> 3544.9722 | R22: =IFERROR('PILE-4C'!K21,"0") -> 3337.5721 | S22: =IFERROR('PILE-4D'!K25,"0") -> 3248 | T22: 3200 | U22: =SUMPRODUCT(D22:T22,D23:T23)/U23 -> 3296.1906
B23: ='PILE-1A'!J26 -> TOP QNTY | C23: =U23 -> 115262 | D23: =IFERROR('PILE-1A'!K26,"0") -> 10140 | E23: =IFERROR('PILE-1B'!K26,"0") -> 21723 | F23: =IFERROR('PILE-1C'!K26,"0") -> 10680 | G23: =IFERROR('PILE-1D'!K22,"0") -> 14369 | H23: =IFERROR('PILE-2A'!K26,"0") -> 0 | I23: =IFERROR('PILE-2B'!K26,"0") -> 0 | J23: =IFERROR('PILE-2C'!K26,"0") -> 8800 | K23: =IFERROR('PILE-2D'!K26,"0") -> 0 | L23: =IFERROR('PILE-3A'!K23,"0") -> 0 | M23: =IFERROR('PILE-3B'!K26,"0") -> 3032 | N23: =IFERROR('PILE-3C'!K26,"0") -> 3348 | O23: =IFERROR('PILE-3D'!K24,"0") -> 10173 | P23: =IFERROR('PILE-4A'!K26,"0") -> 12261 | Q23: =IFERROR('PILE-4B'!K25,"0") -> 9297 | R23: =IFERROR('PILE-4C'!K22,"0") -> 5202 | S23: =IFERROR('PILE-4D'!K26,"0") -> 2237 | T23: 4000 | U23: =SUM(D23:T23) -> 115262
B24: ='PILE-1A'!J27 -> BOTTOM GCV | C24: =U24 -> 3234.2522 | D24: =IFERROR('PILE-1A'!K27,"0") -> 3147.8794 | E24: =IFERROR('PILE-1B'!K27,"0") -> 2772.6332 | F24: =IFERROR('PILE-1C'!K27,"0") -> 3552.1039 | G24: =IFERROR('PILE-1D'!K23,"0") -> 3382.8842 | H24: =IFERROR('PILE-2A'!K27,"0") -> 2654.5665 | I24: =IFERROR('PILE-2B'!K27,"0") -> 3317.6894 | J24: =IFERROR('PILE-2C'!K27,"0") -> 3128.8261 | K24: =IFERROR('PILE-2D'!K27,"0") -> 3637 | L24: =IFERROR('PILE-3A'!K24,"0") -> 3090.8703 | M24: =IFERROR('PILE-3B'!K27,"0") -> 3022.4934 | N24: =IFERROR('PILE-3C'!K27,"0") -> 3082.9437 | O24: =IFERROR('PILE-3D'!K25,"0") -> 3203.6368 | P24: =IFERROR('PILE-4A'!K27,"0") -> 3234.7771 | Q24: =IFERROR('PILE-4B'!K26,"0") -> 3321.6321 | R24: =IFERROR('PILE-4C'!K23,"0") -> 3565.9083 | S24: =IFERROR('PILE-4D'!K27,"0") -> 3371.1751 | T24: 3200 | U24: =SUMPRODUCT(D24:S24,D25:S25)/U25 -> 3234.2522
B25: ='PILE-1A'!J28 -> BOTTOM QNTY | C25: =U25 -> 164233 | D25: =IFERROR('PILE-1A'!K28,"0") -> 11145 | E25: =IFERROR('PILE-1B'!K28,"0") -> 7660 | F25: =IFERROR('PILE-1C'!K28,"0") -> 6516 | G25: =IFERROR('PILE-1D'!K24,"0") -> 11057 | H25: =IFERROR('PILE-2A'!K28,"0") -> 7950 | I25: =IFERROR('PILE-2B'!K28,"0") -> 8405 | J25: =IFERROR('PILE-2C'!K28,"0") -> 16469 | K25: =IFERROR('PILE-2D'!K28,"0") -> 7506 | L25: =IFERROR('PILE-3A'!K25,"0") -> 10277 | M25: =IFERROR('PILE-3B'!K28,"0") -> 7376 | N25: =IFERROR('PILE-3C'!K28,"0") -> 8666 | O25: =IFERROR('PILE-3D'!K26,"0") -> 11452 | P25: =IFERROR('PILE-4A'!K28,"0") -> 9213 | Q25: =IFERROR('PILE-4B'!K27,"0") -> 8343 | R25: =IFERROR('PILE-4C'!K24,"0") -> 15197 | S25: =IFERROR('PILE-4D'!K28,"0") -> 17001 | T25: 4000 | U25: =SUM(D25:S25) -> 164233
B26: ='PILE-1A'!J29 -> MAX AGING | C26: =U26 -> 141 | D26: =IFERROR('PILE-1A'!K29,"0") -> 109 | E26: =IFERROR('PILE-1B'!K29,"0") -> 141 | F26: =IFERROR('PILE-1C'!K29,"0") -> 105 | G26: =IFERROR('PILE-1D'!K25,"0") -> 102 | H26: =IFERROR('PILE-2A'!K29,"0") -> 67 | I26: =IFERROR('PILE-2B'!K29,"0") -> 65 | J26: =IFERROR('PILE-2C'!K29,"0") -> 114 | K26: =IFERROR('PILE-2D'!K29,"0") -> 64 | L26: =IFERROR('PILE-3A'!K26,"0") -> 133 | M26: =IFERROR('PILE-3B'!K29,"0") -> 136 | N26: =IFERROR('PILE-3C'!K29,"0") -> 69 | O26: =IFERROR('PILE-3D'!K27,"0") -> 73 | P26: =IFERROR('PILE-4A'!K29,"0") -> 114 | Q26: =IFERROR('PILE-4B'!K28,"0") -> 113 | R26: =IFERROR('PILE-4C'!K25,"0") -> 103 | S26: =IFERROR('PILE-4D'!K29,"0") -> 100 | T26: 0 | U26: =MAX(D26:T26) -> 141
B27: ='PILE-1A'!J30 -> AVERAGE AGING | C27: =U27 -> 85.52479 | D27: =IFERROR('PILE-1A'!K30,"0") -> 98.166667 | E27: =IFERROR('PILE-1B'!K30,"0") -> 99.1 | F27: =IFERROR('PILE-1C'!K30,"0") -> 98.333333 | G27: =IFERROR('PILE-1D'!K26,"0") -> 94 | H27: =IFERROR('PILE-2A'!K30,"0") -> 65.5 | I27: =IFERROR('PILE-2B'!K30,"0") -> 64.5 | J27: =IFERROR('PILE-2C'!K30,"0") -> 95.75 | K27: =IFERROR('PILE-2D'!K30,"0") -> 63.5 | L27: =IFERROR('PILE-3A'!K27,"0") -> 115.33333 | M27: =IFERROR('PILE-3B'!K30,"0") -> 134.8 | N27: =IFERROR('PILE-3C'!K30,"0") -> 68 | O27: =IFERROR('PILE-3D'!K28,"0") -> 70.666667 | P27: =IFERROR('PILE-4A'!K30,"0") -> 86.5 | Q27: =IFERROR('PILE-4B'!K29,"0") -> 103.6 | R27: =IFERROR('PILE-4C'!K26,"0") -> 100.57143 | S27: =IFERROR('PILE-4D'!K30,"0") -> 95.6 | T27: 0 | U27: =AVERAGE(D27:T27) -> 85.52479
B28: ='PILE-1A'!J31 -> >3500 | C28: =U28 -> 89439 | D28: =IFERROR('PILE-1A'!K31,"0") -> 6801 | E28: =IFERROR('PILE-1B'!K31,"0") -> 0 | F28: =IFERROR('PILE-1C'!K31,"0") -> 13524 | G28: =IFERROR('PILE-1D'!K27,"0") -> 13719 | H28: =IFERROR('PILE-2A'!K31,"0") -> 0 | I28: =IFERROR('PILE-2B'!K31,"0") -> 0 | J28: =IFERROR('PILE-2C'!K31,"0") -> 8469 | K28: =IFERROR('PILE-2D'!K31,"0") -> 7506 | L28: =IFERROR('PILE-3A'!K28,"0") -> 0 | M28: =IFERROR('PILE-3B'!K31,"0") -> 0 | N28: =IFERROR('PILE-3C'!K31,"0") -> 0 | O28: =IFERROR('PILE-3D'!K29,"0") -> 6529 | P28: =IFERROR('PILE-4A'!K31,"0") -> 2453 | Q28: =IFERROR('PILE-4B'!K30,"0") -> 5817 | R28: =IFERROR('PILE-4C'!K27,"0") -> 9087 | S28: =IFERROR('PILE-4D'!K31,"0") -> 7534 | T28: 8000 | U28: =SUM(D28:T28) -> 89439 | W28: =C28/C20 -> 0.31548705
B29: ='PILE-1A'!J32 -> 3100-3500 | C29: =U29 -> 134412 | D29: =IFERROR('PILE-1A'!K32,"0") -> 6477 | E29: =IFERROR('PILE-1B'!K32,"0") -> 8163 | F29: =IFERROR('PILE-1C'!K32,"0") -> 3672 | G29: =IFERROR('PILE-1D'!K28,"0") -> 10350 | H29: =IFERROR('PILE-2A'!K32,"0") -> 0 | I29: =IFERROR('PILE-2B'!K32,"0") -> 8405 | J29: =IFERROR('PILE-2C'!K32,"0") -> 3200 | K29: =IFERROR('PILE-2D'!K32,"0") -> 0 | L29: =IFERROR('PILE-3A'!K29,"0") -> 7144 | M29: =IFERROR('PILE-3B'!K32,"0") -> 6868 | N29: =IFERROR('PILE-3C'!K32,"0") -> 8364 | O29: =IFERROR('PILE-3D'!K30,"0") -> 7110 | P29: =IFERROR('PILE-4A'!K32,"0") -> 12620 | Q29: =IFERROR('PILE-4B'!K31,"0") -> 11823 | R29: =IFERROR('PILE-4C'!K28,"0") -> 11312 | S29: =IFERROR('PILE-4D'!K32,"0") -> 7304 | T29: =WT!K46 -> 21600 | U29: =SUM(D29:T29) -> 134412 | W29: =C29/C20 -> 0.47412476
B30: ='PILE-1A'!J33 -> <3100 | C30: =U30 -> 81244 | D30: =IFERROR('PILE-1A'!K33,"0") -> 8007 | E30: =IFERROR('PILE-1B'!K33,"0") -> 21220 | F30: =IFERROR('PILE-1C'!K33,"0") -> 0 | G30: =IFERROR('PILE-1D'!K29,"0") -> 1357 | H30: =IFERROR('PILE-2A'!K33,"0") -> 7950 | I30: =IFERROR('PILE-2B'!K33,"0") -> 0 | J30: =IFERROR('PILE-2C'!K33,"0") -> 13600 | K30: =IFERROR('PILE-2D'!K33,"0") -> 0 | L30: =IFERROR('PILE-3A'!K30,"0") -> 3133 | M30: =IFERROR('PILE-3B'!K33,"0") -> 3540 | N30: =IFERROR('PILE-3C'!K33,"0") -> 3650 | O30: =IFERROR('PILE-3D'!K31,"0") -> 7986 | P30: =IFERROR('PILE-4A'!K33,"0") -> 6401 | Q30: =IFERROR('PILE-4B'!K32,"0") -> 0 | R30: =IFERROR('PILE-4C'!K29,"0") -> 0 | S30: =IFERROR('PILE-4D'!K33,"0") -> 4400 | T30: =WT!K47 -> 0 | U30: =SUM(D30:T30) -> 81244 | W30: =C30/C20 -> 0.28658001
B31: LAST COAL RAKE GCV
B32: SPUR | C32: NO OF RAKES | D32: 1 | E32: 2 | F32: 3 | G32: 4 | H32: 5 | I32: 6 | J32: 7 | K32: 8 | L32: 9 | M32: 10 | N32: SILO | O32: DB
B33: LAST RAKE AVG GCV | C33: 10 | D33: ='RAKE GCV '!AF1 -> 3008.1975 | E33: ='RAKE GCV '!AG1 -> 2907.2236 | F33: ='RAKE GCV '!AH1 -> 2861.7378 | G33: ='RAKE GCV '!AI1 -> 2894.5166 | H33: ='RAKE GCV '!AJ1 -> 3602.6717 | I33: ='RAKE GCV '!AK1 -> 3403.274 | J33: ='RAKE GCV '!AL1 -> 3117.3581 | K33: ='RAKE GCV '!AM1 -> 3025.371 | ... O33: ='RAKE GCV '!AQ1 -> 3111.93

Sheet RAKE GCV 
A1: Sl. No. | B1: Sample Collection Date | C1: Rake_No | D1: SIDING NO | E1: ARBG.C.V-k.cal/kg | F1: 1 | G1: 2 | H1: 3 | I1: 4 | J1: 5 | K1: 6 | L1: 7 | M1: 8 | N1: 9 | O1: 10 | P1: SILO | Q1: DB | AF1: =AVERAGEIF((AF2:AF1362),">0") -> 3008.1975 | AG1: =AVERAGEIF((AG2:AG1362),">0") -> 2907.2236 | AH1: =AVERAGEIF((AH2:AH1362),">0") -> 2861.7378 | AI1: =AVERAGEIF((AI2:AI1362),">0") -> 2894.5166 | AJ1: =AVERAGEIF((AJ2:AJ1362),">0") -> 3602.6717 | AK1: =AVERAGEIF((AK2:AK1362),">0") -> 3403.274 | AL1: =AVERAGEIF((AL2:AL1362),">0") -> 3117.3581 | AM1: =AVERAGEIF((AM2:AM1362),">0") -> 3025.371 | ... AQ1: =AVERAGEIF((AQ2:AQ1362),">0") -> 3111.93 | AT1: ='summery '!C33 -> 10
A2: 1 | B2: 01.03.2024 | C2: MGBK-01 | D2: SPUR-06 | E2: 3207.2522 | F2: =IF(D2="SPUR-01",E2,0) -> 0 | G2: =IF(D2="SPUR-02",E2,0) -> 0 | H2: =IF(D2="SPUR-03",E2,0) -> 0 | I2: =IF(D2="SPUR-04",E2,0) -> 0 | J2: =IF(D2="SPUR-05",E2,0) -> 0 | K2: =IF(D2="SPUR-06",E2,0) -> 3207.2522 | L2: =IF(D2="SPUR-07",E2,0) -> 0 | M2: =IF(D2="SPUR-08",E2,0) -> 0 | N2: =IF(D2="SPUR-09",E2,0) -> 0 | O2: =IF(D2="SPUR-10",E2,0) -> 0 | P2: =IF(D2="SPUR-SILO",E2,0) -> 0 | Q2: =IF(D2="SPUR-DB",E2,0) -> 0 | S2: =IF(F2>0,1,0)+S3 -> 58 | T2: =IF(G2>0,1,0)+T3 -> 39 | U2: =IF(H2>0,1,0)+U3 -> 42 | V2: =IF(I2>0,1,0)+V3 -> 49 | W2: =IF(J2>0,1,0)+W3 -> 133 | X2: =IF(K2>0,1,0)+X3 -> 130 | Y2: =IF(L2>0,1,0)+Y3 -> 59 | Z2: =IF(M2>0,1,0)+Z3 -> 45 | ... AD2: =IF(Q2>0,1,0)+AD3 -> 46 | AF2: =IF(S2<=$AT$1,F2,0) -> 0 | AG2: =IF(T2<=$AT$1,G2,0) -> 0 | AH2: =IF(U2<=$AT$1,H2,0) -> 0 | AI2: =IF(V2<=$AT$1,I2,0) -> 0 | AJ2: =IF(W2<=$AT$1,J2,0) -> 0 | AK2: =IF(X2<=$AT$1,K2,0) -> 0 | AL2: =IF(Y2<=$AT$1,L2,0) -> 0 | AM2: =IF(Z2<=$AT$1,M2,0) -> 0 | ... AQ2: =IF(AD2<=$AT$1,Q2,0) -> 0
A3: 2 | B3: 02.03.2024 | C3: MGBK-02 | D3: SPUR-08 | E3: 3403.105 | F3: =IF(D3="SPUR-01",E3,0) -> 0 | G3: =IF(D3="SPUR-02",E3,0) -> 0 | H3: =IF(D3="SPUR-03",E3,0) -> 0 | I3: =IF(D3="SPUR-04",E3,0) -> 0 | J3: =IF(D3="SPUR-05",E3,0) -> 0 | K3: =IF(D3="SPUR-06",E3,0) -> 0 | L3: =IF(D3="SPUR-07",E3,0) -> 0 | M3: =IF(D3="SPUR-08",E3,0) -> 3403.105 | N3: =IF(D3="SPUR-09",E3,0) -> 0 | O3: =IF(D3="SPUR-10",E3,0) -> 0 | P3: =IF(D3="SPUR-SILO",E3,0) -> 0 | Q3: =IF(D3="SPUR-DB",E3,0) -> 0 | S3: =IF(F3>0,1,0)+S4 -> 58 | T3: =IF(G3>0,1,0)+T4 -> 39 | U3: =IF(H3>0,1,0)+U4 -> 42 | V3: =IF(I3>0,1,0)+V4 -> 49 | W3: =IF(J3>0,1,0)+W4 -> 133 | X3: =IF(K3>0,1,0)+X4 -> 129 | Y3: =IF(L3>0,1,0)+Y4 -> 59 | Z3: =IF(M3>0,1,0)+Z4 -> 45 | ... AD3: =IF(Q3>0,1,0)+AD4 -> 46 | AF3: =IF(S3<=$AT$1,F3,0) -> 0 | AG3: =IF(T3<=$AT$1,G3,0) -> 0 | AH3: =IF(U3<=$AT$1,H3,0) -> 0 | AI3: =IF(V3<=$AT$1,I3,0) -> 0 | AJ3: =IF(W3<=$AT$1,J3,0) -> 0 | AK3: =IF(X3<=$AT$1,K3,0) -> 0 | AL3: =IF(Y3<=$AT$1,L3,0) -> 0 | AM3: =IF(Z3<=$AT$1,M3,0) -> 0 | ... AQ3: =IF(AD3<=$AT$1,Q3,0) -> 0
A4: 3 | B4: 02.03.2024 | C4: MGBK-03 | D4: SPUR-DB | E4: 2979.6964 | F4: =IF(D4="SPUR-01",E4,0) -> 0 | G4: =IF(D4="SPUR-02",E4,0) -> 0 | H4: =IF(D4="SPUR-03",E4,0) -> 0 | I4: =IF(D4="SPUR-04",E4,0) -> 0 | J4: =IF(D4="SPUR-05",E4,0) -> 0 | K4: =IF(D4="SPUR-06",E4,0) -> 0 | L4: =IF(D4="SPUR-07",E4,0) -> 0 | M4: =IF(D4="SPUR-08",E4,0) -> 0 | N4: =IF(D4="SPUR-09",E4,0) -> 0 | O4: =IF(D4="SPUR-10",E4,0) -> 0 | P4: =IF(D4="SPUR-SILO",E4,0) -> 0 | Q4: =IF(D4="SPUR-DB",E4,0) -> 2979.6964 | S4: =IF(F4>0,1,0)+S5 -> 58 | T4: =IF(G4>0,1,0)+T5 -> 39 | U4: =IF(H4>0,1,0)+U5 -> 42 | V4: =IF(I4>0,1,0)+V5 -> 49 | W4: =IF(J4>0,1,0)+W5 -> 133 | X4: =IF(K4>0,1,0)+X5 -> 129 | Y4: =IF(L4>0,1,0)+Y5 -> 59 | Z4: =IF(M4>0,1,0)+Z5 -> 44 | ... AD4: =IF(Q4>0,1,0)+AD5 -> 46 | AF4: =IF(S4<=$AT$1,F4,0) -> 0 | AG4: =IF(T4<=$AT$1,G4,0) -> 0 | AH4: =IF(U4<=$AT$1,H4,0) -> 0 | AI4: =IF(V4<=$AT$1,I4,0) -> 0 | AJ4: =IF(W4<=$AT$1,J4,0) -> 0 | AK4: =IF(X4<=$AT$1,K4,0) -> 0 | AL4: =IF(Y4<=$AT$1,L4,0) -> 0 | AM4: =IF(Z4<=$AT$1,M4,0) -> 0 | ... AQ4: =IF(AD4<=$AT$1,Q4,0) -> 0
A5: 4 | B5: 02.03.2024 | C5: MGBK-04 | D5: SPUR-05 | E5: 3309 | F5: =IF(D5="SPUR-01",E5,0) -> 0 | G5: =IF(D5="SPUR-02",E5,0) -> 0 | H5: =IF(D5="SPUR-03",E5,0) -> 0 | I5: =IF(D5="SPUR-04",E5,0) -> 0 | J5: =IF(D5="SPUR-05",E5,0) -> 3309 | K5: =IF(D5="SPUR-06",E5,0) -> 0 | L5: =IF(D5="SPUR-07",E5,0) -> 0 | M5: =IF(D5="SPUR-08",E5,0) -> 0 | N5: =IF(D5="SPUR-09",E5,0) -> 0 | O5: =IF(D5="SPUR-10",E5,0) -> 0 | P5: =IF(D5="SPUR-SILO",E5,0) -> 0 | Q5: =IF(D5="SPUR-DB",E5,0) -> 0 | S5: =IF(F5>0,1,0)+S6 -> 58 | T5: =IF(G5>0,1,0)+T6 -> 39 | U5: =IF(H5>0,1,0)+U6 -> 42 | V5: =IF(I5>0,1,0)+V6 -> 49 | W5: =IF(J5>0,1,0)+W6 -> 133 | X5: =IF(K5>0,1,0)+X6 -> 129 | Y5: =IF(L5>0,1,0)+Y6 -> 59 | Z5: =IF(M5>0,1,0)+Z6 -> 44 | ... AD5: =IF(Q5>0,1,0)+AD6 -> 45 | AF5: =IF(S5<=$AT$1,F5,0) -> 0 | AG5: =IF(T5<=$AT$1,G5,0) -> 0 | AH5: =IF(U5<=$AT$1,H5,0) -> 0 | AI5: =IF(V5<=$AT$1,I5,0) -> 0 | AJ5: =IF(W5<=$AT$1,J5,0) -> 0 | AK5: =IF(X5<=$AT$1,K5,0) -> 0 | AL5: =IF(Y5<=$AT$1,L5,0) -> 0 | AM5: =IF(Z5<=$AT$1,M5,0) -> 0 | ... AQ5: =IF(AD5<=$AT$1,Q5,0) -> 0
A6: 5 | B6: 02.03.2024 | C6: MGBK-05 | D6: SPUR-06 | E6: 3362 | F6: =IF(D6="SPUR-01",E6,0) -> 0 | G6: =IF(D6="SPUR-02",E6,0) -> 0 | H6: =IF(D6="SPUR-03",E6,0) -> 0 | I6: =IF(D6="SPUR-04",E6,0) -> 0 | J6: =IF(D6="SPUR-05",E6,0) -> 0 | K6: =IF(D6="SPUR-06",E6,0) -> 3362 | L6: =IF(D6="SPUR-07",E6,0) -> 0 | M6: =IF(D6="SPUR-08",E6,0) -> 0 | N6: =IF(D6="SPUR-09",E6,0) -> 0 | O6: =IF(D6="SPUR-10",E6,0) -> 0 | P6: =IF(D6="SPUR-SILO",E6,0) -> 0 | Q6: =IF(D6="SPUR-DB",E6,0) -> 0 | S6: =IF(F6>0,1,0)+S7 -> 58 | T6: =IF(G6>0,1,0)+T7 -> 39 | U6: =IF(H6>0,1,0)+U7 -> 42 | V6: =IF(I6>0,1,0)+V7 -> 49 | W6: =IF(J6>0,1,0)+W7 -> 132 | X6: =IF(K6>0,1,0)+X7 -> 129 | Y6: =IF(L6>0,1,0)+Y7 -> 59 | Z6: =IF(M6>0,1,0)+Z7 -> 44 | ... AD6: =IF(Q6>0,1,0)+AD7 -> 45 | AF6: =IF(S6<=$AT$1,F6,0) -> 0 | AG6: =IF(T6<=$AT$1,G6,0) -> 0 | AH6: =IF(U6<=$AT$1,H6,0) -> 0 | AI6: =IF(V6<=$AT$1,I6,0) -> 0 | AJ6: =IF(W6<=$AT$1,J6,0) -> 0 | AK6: =IF(X6<=$AT$1,K6,0) -> 0 | AL6: =IF(Y6<=$AT$1,L6,0) -> 0 | AM6: =IF(Z6<=$AT$1,M6,0) -> 0 | ... AQ6: =IF(AD6<=$AT$1,Q6,0) -> 0
A7: 6 | B7: 03.03.2024 | C7: MGBK-06 | D7: SPUR-05 | E7: 3144 | F7: =IF(D7="SPUR-01",E7,0) -> 0 | G7: =IF(D7="SPUR-02",E7,0) -> 0 | H7: =IF(D7="SPUR-03",E7,0) -> 0 | I7: =IF(D7="SPUR-04",E7,0) -> 0 | J7: =IF(D7="SPUR-05",E7,0) -> 3144 | K7: =IF(D7="SPUR-06",E7,0) -> 0 | L7: =IF(D7="SPUR-07",E7,0) -> 0 | M7: =IF(D7="SPUR-08",E7,0) -> 0 | N7: =IF(D7="SPUR-09",E7,0) -> 0 | O7: =IF(D7="SPUR-10",E7,0) -> 0 | P7: =IF(D7="SPUR-SILO",E7,0) -> 0 | Q7: =IF(D7="SPUR-DB",E7,0) -> 0 | S7: =IF(F7>0,1,0)+S8 -> 58 | T7: =IF(G7>0,1,0)+T8 -> 39 | U7: =IF(H7>0,1,0)+U8 -> 42 | V7: =IF(I7>0,1,0)+V8 -> 49 | W7: =IF(J7>0,1,0)+W8 -> 132 | X7: =IF(K7>0,1,0)+X8 -> 128 | Y7: =IF(L7>0,1,0)+Y8 -> 59 | Z7: =IF(M7>0,1,0)+Z8 -> 44 | ... AD7: =IF(Q7>0,1,0)+AD8 -> 45 | AF7: =IF(S7<=$AT$1,F7,0) -> 0 | AG7: =IF(T7<=$AT$1,G7,0) -> 0 | AH7: =IF(U7<=$AT$1,H7,0) -> 0 | AI7: =IF(V7<=$AT$1,I7,0) -> 0 | AJ7: =IF(W7<=$AT$1,J7,0) -> 0 | AK7: =IF(X7<=$AT$1,K7,0) -> 0 | AL7: =IF(Y7<=$AT$1,L7,0) -> 0 | AM7: =IF(Z7<=$AT$1,M7,0) -> 0 | ... AQ7: =IF(AD7<=$AT$1,Q7,0) -> 0
A8: 7 | B8: 03.03.2024 | C8: MGBK-07 | D8: SPUR-06 | E8: 3295 | F8: =IF(D8="SPUR-01",E8,0) -> 0 | G8: =IF(D8="SPUR-02",E8,0) -> 0 | H8: =IF(D8="SPUR-03",E8,0) -> 0 | I8: =IF(D8="SPUR-04",E8,0) -> 0 | J8: =IF(D8="SPUR-05",E8,0) -> 0 | K8: =IF(D8="SPUR-06",E8,0) -> 3295 | L8: =IF(D8="SPUR-07",E8,0) -> 0 | M8: =IF(D8="SPUR-08",E8,0) -> 0 | N8: =IF(D8="SPUR-09",E8,0) -> 0 | O8: =IF(D8="SPUR-10",E8,0) -> 0 | P8: =IF(D8="SPUR-SILO",E8,0) -> 0 | Q8: =IF(D8="SPUR-DB",E8,0) -> 0 | S8: =IF(F8>0,1,0)+S9 -> 58 | T8: =IF(G8>0,1,0)+T9 -> 39 | U8: =IF(H8>0,1,0)+U9 -> 42 | V8: =IF(I8>0,1,0)+V9 -> 49 | W8: =IF(J8>0,1,0)+W9 -> 131 | X8: =IF(K8>0,1,0)+X9 -> 128 | Y8: =IF(L8>0,1,0)+Y9 -> 59 | Z8: =IF(M8>0,1,0)+Z9 -> 44 | ... AD8: =IF(Q8>0,1,0)+AD9 -> 45 | AF8: =IF(S8<=$AT$1,F8,0) -> 0 | AG8: =IF(T8<=$AT$1,G8,0) -> 0 | AH8: =IF(U8<=$AT$1,H8,0) -> 0 | AI8: =IF(V8<=$AT$1,I8,0) -> 0 | AJ8: =IF(W8<=$AT$1,J8,0) -> 0 | AK8: =IF(X8<=$AT$1,K8,0) -> 0 | AL8: =IF(Y8<=$AT$1,L8,0) -> 0 | AM8: =IF(Z8<=$AT$1,M8,0) -> 0 | ... AQ8: =IF(AD8<=$AT$1,Q8,0) -> 0
A9: 8 | B9: 03.03.2024 | C9: MGBK-08 | D9: SPUR-08 | E9: 2612 | F9: =IF(D9="SPUR-01",E9,0) -> 0 | G9: =IF(D9="SPUR-02",E9,0) -> 0 | H9: =IF(D9="SPUR-03",E9,0) -> 0 | I9: =IF(D9="SPUR-04",E9,0) -> 0 | J9: =IF(D9="SPUR-05",E9,0) -> 0 | K9: =IF(D9="SPUR-06",E9,0) -> 0 | L9: =IF(D9="SPUR-07",E9,0) -> 0 | M9: =IF(D9="SPUR-08",E9,0) -> 2612 | N9: =IF(D9="SPUR-09",E9,0) -> 0 | O9: =IF(D9="SPUR-10",E9,0) -> 0 | P9: =IF(D9="SPUR-SILO",E9,0) -> 0 | Q9: =IF(D9="SPUR-DB",E9,0) -> 0 | S9: =IF(F9>0,1,0)+S10 -> 58 | T9: =IF(G9>0,1,0)+T10 -> 39 | U9: =IF(H9>0,1,0)+U10 -> 42 | V9: =IF(I9>0,1,0)+V10 -> 49 | W9: =IF(J9>0,1,0)+W10 -> 131 | X9: =IF(K9>0,1,0)+X10 -> 127 | Y9: =IF(L9>0,1,0)+Y10 -> 59 | Z9: =IF(M9>0,1,0)+Z10 -> 44 | ... AD9: =IF(Q9>0,1,0)+AD10 -> 45 | AF9: =IF(S9<=$AT$1,F9,0) -> 0 | AG9: =IF(T9<=$AT$1,G9,0) -> 0 | AH9: =IF(U9<=$AT$1,H9,0) -> 0 | AI9: =IF(V9<=$AT$1,I9,0) -> 0 | AJ9: =IF(W9<=$AT$1,J9,0) -> 0 | AK9: =IF(X9<=$AT$1,K9,0) -> 0 | AL9: =IF(Y9<=$AT$1,L9,0) -> 0 | AM9: =IF(Z9<=$AT$1,M9,0) -> 0 | ... AQ9: =IF(AD9<=$AT$1,Q9,0) -> 0
A10: 9 | B10: 03.03.2024 | C10: MGBK-09 | D10: SPUR-04 | E10: 3391 | F10: =IF(D10="SPUR-01",E10,0) -> 0 | G10: =IF(D10="SPUR-02",E10,0) -> 0 | H10: =IF(D10="SPUR-03",E10,0) -> 0 | I10: =IF(D10="SPUR-04",E10,0) -> 3391 | J10: =IF(D10="SPUR-05",E10,0) -> 0 | K10: =IF(D10="SPUR-06",E10,0) -> 0 | L10: =IF(D10="SPUR-07",E10,0) -> 0 | M10: =IF(D10="SPUR-08",E10,0) -> 0 | N10: =IF(D10="SPUR-09",E10,0) -> 0 | O10: =IF(D10="SPUR-10",E10,0) -> 0 | P10: =IF(D10="SPUR-SILO",E10,0) -> 0 | Q10: =IF(D10="SPUR-DB",E10,0) -> 0 | S10: =IF(F10>0,1,0)+S11 -> 58 | T10: =IF(G10>0,1,0)+T11 -> 39 | U10: =IF(H10>0,1,0)+U11 -> 42 | V10: =IF(I10>0,1,0)+V11 -> 49 | W10: =IF(J10>0,1,0)+W11 -> 131 | X10: =IF(K10>0,1,0)+X11 -> 127 | Y10: =IF(L10>0,1,0)+Y11 -> 59 | Z10: =IF(M10>0,1,0)+Z11 -> 43 | ... AD10: =IF(Q10>0,1,0)+AD11 -> 45 | AF10: =IF(S10<=$AT$1,F10,0) -> 0 | AG10: =IF(T10<=$AT$1,G10,0) -> 0 | AH10: =IF(U10<=$AT$1,H10,0) -> 0 | AI10: =IF(V10<=$AT$1,I10,0) -> 0 | AJ10: =IF(W10<=$AT$1,J10,0) -> 0 | AK10: =IF(X10<=$AT$1,K10,0) -> 0 | AL10: =IF(Y10<=$AT$1,L10,0) -> 0 | AM10: =IF(Z10<=$AT$1,M10,0) -> 0 | ... AQ10: =IF(AD10<=$AT$1,Q10,0) -> 0
A11: 10 | B11: 04.03.2024 | C11: MGBK-11 | D11: SPUR-SILO | E11: 3165 | F11: =IF(D11="SPUR-01",E11,0) -> 0 | G11: =IF(D11="SPUR-02",E11,0) -> 0 | H11: =IF(D11="SPUR-03",E11,0) -> 0 | I11: =IF(D11="SPUR-04",E11,0) -> 0 | J11: =IF(D11="SPUR-05",E11,0) -> 0 | K11: =IF(D11="SPUR-06",E11,0) -> 0 | L11: =IF(D11="SPUR-07",E11,0) -> 0 | M11: =IF(D11="SPUR-08",E11,0) -> 0 | N11: =IF(D11="SPUR-09",E11,0) -> 0 | O11: =IF(D11="SPUR-10",E11,0) -> 0 | P11: =IF(D11="SPUR-SILO",E11,0) -> 3165 | Q11: =IF(D11="SPUR-DB",E11,0) -> 0 | S11: =IF(F11>0,1,0)+S12 -> 58 | T11: =IF(G11>0,1,0)+T12 -> 39 | U11: =IF(H11>0,1,0)+U12 -> 42 | V11: =IF(I11>0,1,0)+V12 -> 48 | W11: =IF(J11>0,1,0)+W12 -> 131 | X11: =IF(K11>0,1,0)+X12 -> 127 | Y11: =IF(L11>0,1,0)+Y12 -> 59 | Z11: =IF(M11>0,1,0)+Z12 -> 43 | ... AD11: =IF(Q11>0,1,0)+AD12 -> 45 | AF11: =IF(S11<=$AT$1,F11,0) -> 0 | AG11: =IF(T11<=$AT$1,G11,0) -> 0 | AH11: =IF(U11<=$AT$1,H11,0) -> 0 | AI11: =IF(V11<=$AT$1,I11,0) -> 0 | AJ11: =IF(W11<=$AT$1,J11,0) -> 0 | AK11: =IF(X11<=$AT$1,K11,0) -> 0 | AL11: =IF(Y11<=$AT$1,L11,0) -> 0 | AM11: =IF(Z11<=$AT$1,M11,0) -> 0 | ... AQ11: =IF(AD11<=$AT$1,Q11,0) -> 0
A12: 11 | B12: 04.03.2024 | C12: NMGBK-10 | D12: SPUR-06 | E12: 3770 | F12: =IF(D12="SPUR-01",E12,0) -> 0 | G12: =IF(D12="SPUR-02",E12,0) -> 0 | H12: =IF(D12="SPUR-03",E12,0) -> 0 | I12: =IF(D12="SPUR-04",E12,0) -> 0 | J12: =IF(D12="SPUR-05",E12,0) -> 0 | K12: =IF(D12="SPUR-06",E12,0) -> 3770 | L12: =IF(D12="SPUR-07",E12,0) -> 0 | M12: =IF(D12="SPUR-08",E12,0) -> 0 | N12: =IF(D12="SPUR-09",E12,0) -> 0 | O12: =IF(D12="SPUR-10",E12,0) -> 0 | P12: =IF(D12="SPUR-SILO",E12,0) -> 0 | Q12: =IF(D12="SPUR-DB",E12,0) -> 0 | S12: =IF(F12>0,1,0)+S13 -> 58 | T12: =IF(G12>0,1,0)+T13 -> 39 | U12: =IF(H12>0,1,0)+U13 -> 42 | V12: =IF(I12>0,1,0)+V13 -> 48 | W12: =IF(J12>0,1,0)+W13 -> 131 | X12: =IF(K12>0,1,0)+X13 -> 127 | Y12: =IF(L12>0,1,0)+Y13 -> 59 | Z12: =IF(M12>0,1,0)+Z13 -> 43 | ... AD12: =IF(Q12>0,1,0)+AD13 -> 45 | AF12: =IF(S12<=$AT$1,F12,0) -> 0 | AG12: =IF(T12<=$AT$1,G12,0) -> 0 | AH12: =IF(U12<=$AT$1,H12,0) -> 0 | AI12: =IF(V12<=$AT$1,I12,0) -> 0 | AJ12: =IF(W12<=$AT$1,J12,0) -> 0 | AK12: =IF(X12<=$AT$1,K12,0) -> 0 | AL12: =IF(Y12<=$AT$1,L12,0) -> 0 | AM12: =IF(Z12<=$AT$1,M12,0) -> 0 | ... AQ12: =IF(AD12<=$AT$1,Q12,0) -> 0
A13: 12 | B13: 04.03.2024 | C13: MGBK-13 | D13: SPUR-04 | E13: 3346 | F13: =IF(D13="SPUR-01",E13,0) -> 0 | G13: =IF(D13="SPUR-02",E13,0) -> 0 | H13: =IF(D13="SPUR-03",E13,0) -> 0 | I13: =IF(D13="SPUR-04",E13,0) -> 3346 | J13: =IF(D13="SPUR-05",E13,0) -> 0 | K13: =IF(D13="SPUR-06",E13,0) -> 0 | L13: =IF(D13="SPUR-07",E13,0) -> 0 | M13: =IF(D13="SPUR-08",E13,0) -> 0 | N13: =IF(D13="SPUR-09",E13,0) -> 0 | O13: =IF(D13="SPUR-10",E13,0) -> 0 | P13: =IF(D13="SPUR-SILO",E13,0) -> 0 | Q13: =IF(D13="SPUR-DB",E13,0) -> 0 | S13: =IF(F13>0,1,0)+S14 -> 58 | T13: =IF(G13>0,1,0)+T14 -> 39 | U13: =IF(H13>0,1,0)+U14 -> 42 | V13: =IF(I13>0,1,0)+V14 -> 48 | W13: =IF(J13>0,1,0)+W14 -> 131 | X13: =IF(K13>0,1,0)+X14 -> 126 | Y13: =IF(L13>0,1,0)+Y14 -> 59 | Z13: =IF(M13>0,1,0)+Z14 -> 43 | ... AD13: =IF(Q13>0,1,0)+AD14 -> 45 | AF13: =IF(S13<=$AT$1,F13,0) -> 0 | AG13: =IF(T13<=$AT$1,G13,0) -> 0 | AH13: =IF(U13<=$AT$1,H13,0) -> 0 | AI13: =IF(V13<=$AT$1,I13,0) -> 0 | AJ13: =IF(W13<=$AT$1,J13,0) -> 0 | AK13: =IF(X13<=$AT$1,K13,0) -> 0 | AL13: =IF(Y13<=$AT$1,L13,0) -> 0 | AM13: =IF(Z13<=$AT$1,M13,0) -> 0 | ... AQ13: =IF(AD13<=$AT$1,Q13,0) -> 0
... A113: 112 | B113: 31.03.2024 | C113: MGBK-111 | D113: SPUR-04 | E113: 2732 | F113: =IF(D113="SPUR-01",E113,0) -> 0 | G113: =IF(D113="SPUR-02",E113,0) -> 0 | H113: =IF(D113="SPUR-03",E113,0) -> 0 | I113: =IF(D113="SPUR-04",E113,0) -> 2732 | J113: =IF(D113="SPUR-05",E113,0) -> 0 | K113: =IF(D113="SPUR-06",E113,0) -> 0 | L113: =IF(D113="SPUR-07",E113,0) -> 0 | M113: =IF(D113="SPUR-08",E113,0) -> 0 | N113: =IF(D113="SPUR-09",E113,0) -> 0 | O113: =IF(D113="SPUR-10",E113,0) -> 0 | P113: =IF(D113="SPUR-SILO",E113,0) -> 0 | Q113: =IF(D113="SPUR-DB",E113,0) -> 0 | S113: =IF(F113>0,1,0)+S114 -> 57 | T113: =IF(G113>0,1,0)+T114 -> 39 | U113: =IF(H113>0,1,0)+U114 -> 32 | V113: =IF(I113>0,1,0)+V114 -> 37 | W113: =IF(J113>0,1,0)+W114 -> 113 | X113: =IF(K113>0,1,0)+X114 -> 104 | Y113: =IF(L113>0,1,0)+Y114 -> 46 | Z113: =IF(M113>0,1,0)+Z114 -> 33 | ... AD113: =IF(Q113>0,1,0)+AD114 -> 37 | AF113: =IF(S113<=$AT$1,F113,0) -> 0 | AG113: =IF(T113<=$AT$1,G113,0) -> 0 | AH113: =IF(U113<=$AT$1,H113,0) -> 0 | AI113: =IF(V113<=$AT$1,I113,0) -> 0 | AJ113: =IF(W113<=$AT$1,J113,0) -> 0 | AK113: =IF(X113<=$AT$1,K113,0) -> 0 | AL113: =IF(Y113<=$AT$1,L113,0) -> 0 | AM113: =IF(Z113<=$AT$1,M113,0) -> 0 | ... AQ113: =IF(AD113<=$AT$1,Q113,0) -> 0
F114: =IF(D114="SPUR-01",E114,0) -> 0 | G114: =IF(D114="SPUR-02",E114,0) -> 0 | H114: =IF(D114="SPUR-03",E114,0) -> 0 | I114: =IF(D114="SPUR-04",E114,0) -> 0 | J114: =IF(D114="SPUR-05",E114,0) -> 0 | K114: =IF(D114="SPUR-06",E114,0) -> 0 | L114: =IF(D114="SPUR-07",E114,0) -> 0 | M114: =IF(D114="SPUR-08",E114,0) -> 0 | N114: =IF(D114="SPUR-09",E114,0) -> 0 | O114: =IF(D114="SPUR-10",E114,0) -> 0 | P114: =IF(D114="SPUR-SILO",E114,0) -> 0 | Q114: =IF(D114="SPUR-DB",E114,0) -> 0 | S114: =IF(F114>0,1,0)+S115 -> 57 | T114: =IF(G114>0,1,0)+T115 -> 39 | U114: =IF(H114>0,1,0)+U115 -> 32 | V114: =IF(I114>0,1,0)+V115 -> 36 | W114: =IF(J114>0,1,0)+W115 -> 113 | X114: =IF(K114>0,1,0)+X115 -> 104 | Y114: =IF(L114>0,1,0)+Y115 -> 46 | Z114: =IF(M114>0,1,0)+Z115 -> 33 | ... AD114: =IF(Q114>0,1,0)+AD115 -> 37 | AF114: =IF(S114<=$AT$1,F114,0) -> 0 | AG114: =IF(T114<=$AT$1,G114,0) -> 0 | AH114: =IF(U114<=$AT$1,H114,0) -> 0 | AI114: =IF(V114<=$AT$1,I114,0) -> 0 | AJ114: =IF(W114<=$AT$1,J114,0) -> 0 | AK114: =IF(X114<=$AT$1,K114,0) -> 0 | AL114: =IF(Y114<=$AT$1,L114,0) -> 0 | AM114: =IF(Z114<=$AT$1,M114,0) -> 0 | ... AQ114: =IF(AD114<=$AT$1,Q114,0) -> 0
A115: 1 | B115: 01.04.2024 | C115: MGBK-1 | D115: SPUR-05 | E115: 2766.7041 | F115: =IF(D115="SPUR-01",E115,0) -> 0 | G115: =IF(D115="SPUR-02",E115,0) -> 0 | H115: =IF(D115="SPUR-03",E115,0) -> 0 | I115: =IF(D115="SPUR-04",E115,0) -> 0 | J115: =IF(D115="SPUR-05",E115,0) -> 2766.7041 | K115: =IF(D115="SPUR-06",E115,0) -> 0 | L115: =IF(D115="SPUR-07",E115,0) -> 0 | M115: =IF(D115="SPUR-08",E115,0) -> 0 | N115: =IF(D115="SPUR-09",E115,0) -> 0 | O115: =IF(D115="SPUR-10",E115,0) -> 0 | P115: =IF(D115="SPUR-SILO",E115,0) -> 0 | Q115: =IF(D115="SPUR-DB",E115,0) -> 0 | S115: =IF(F115>0,1,0)+S116 -> 57 | T115: =IF(G115>0,1,0)+T116 -> 39 | U115: =IF(H115>0,1,0)+U116 -> 32 | V115: =IF(I115>0,1,0)+V116 -> 36 | W115: =IF(J115>0,1,0)+W116 -> 113 | X115: =IF(K115>0,1,0)+X116 -> 104 | Y115: =IF(L115>0,1,0)+Y116 -> 46 | Z115: =IF(M115>0,1,0)+Z116 -> 33 | ... AD115: =IF(Q115>0,1,0)+AD116 -> 37 | AF115: =IF(S115<=$AT$1,F115,0) -> 0 | AG115: =IF(T115<=$AT$1,G115,0) -> 0 | AH115: =IF(U115<=$AT$1,H115,0) -> 0 | AI115: =IF(V115<=$AT$1,I115,0) -> 0 | AJ115: =IF(W115<=$AT$1,J115,0) -> 0 | AK115: =IF(X115<=$AT$1,K115,0) -> 0 | AL115: =IF(Y115<=$AT$1,L115,0) -> 0 | AM115: =IF(Z115<=$AT$1,M115,0) -> 0 | ... AQ115: =IF(AD115<=$AT$1,Q115,0) -> 0
A116: 2 | B116: 02.04.2024 | C116: MGBK-2 | D116: SPUR-04 | E116: 3186.843 | F116: =IF(D116="SPUR-01",E116,0) -> 0 | G116: =IF(D116="SPUR-02",E116,0) -> 0 | H116: =IF(D116="SPUR-03",E116,0) -> 0 | I116: =IF(D116="SPUR-04",E116,0) -> 3186.843 | J116: =IF(D116="SPUR-05",E116,0) -> 0 | K116: =IF(D116="SPUR-06",E116,0) -> 0 | L116: =IF(D116="SPUR-07",E116,0) -> 0 | M116: =IF(D116="SPUR-08",E116,0) -> 0 | N116: =IF(D116="SPUR-09",E116,0) -> 0 | O116: =IF(D116="SPUR-10",E116,0) -> 0 | P116: =IF(D116="SPUR-SILO",E116,0) -> 0 | Q116: =IF(D116="SPUR-DB",E116,0) -> 0 | S116: =IF(F116>0,1,0)+S117 -> 57 | T116: =IF(G116>0,1,0)+T117 -> 39 | U116: =IF(H116>0,1,0)+U117 -> 32 | V116: =IF(I116>0,1,0)+V117 -> 36 | W116: =IF(J116>0,1,0)+W117 -> 112 | X116: =IF(K116>0,1,0)+X117 -> 104 | Y116: =IF(L116>0,1,0)+Y117 -> 46 | Z116: =IF(M116>0,1,0)+Z117 -> 33 | ... AD116: =IF(Q116>0,1,0)+AD117 -> 37 | AF116: =IF(S116<=$AT$1,F116,0) -> 0 | AG116: =IF(T116<=$AT$1,G116,0) -> 0 | AH116: =IF(U116<=$AT$1,H116,0) -> 0 | AI116: =IF(V116<=$AT$1,I116,0) -> 0 | AJ116: =IF(W116<=$AT$1,J116,0) -> 0 | AK116: =IF(X116<=$AT$1,K116,0) -> 0 | AL116: =IF(Y116<=$AT$1,L116,0) -> 0 | AM116: =IF(Z116<=$AT$1,M116,0) -> 0 | ... AQ116: =IF(AD116<=$AT$1,Q116,0) -> 0
A117: 3 | B117: 02.04.2024 | C117: MGBK-4 | D117: SPUR-SILO | E117: 3029.2978 | F117: =IF(D117="SPUR-01",E117,0) -> 0 | G117: =IF(D117="SPUR-02",E117,0) -> 0 | H117: =IF(D117="SPUR-03",E117,0) -> 0 | I117: =IF(D117="SPUR-04",E117,0) -> 0 | J117: =IF(D117="SPUR-05",E117,0) -> 0 | K117: =IF(D117="SPUR-06",E117,0) -> 0 | L117: =IF(D117="SPUR-07",E117,0) -> 0 | M117: =IF(D117="SPUR-08",E117,0) -> 0 | N117: =IF(D117="SPUR-09",E117,0) -> 0 | O117: =IF(D117="SPUR-10",E117,0) -> 0 | P117: =IF(D117="SPUR-SILO",E117,0) -> 3029.2978 | Q117: =IF(D117="SPUR-DB",E117,0) -> 0 | S117: =IF(F117>0,1,0)+S118 -> 57 | T117: =IF(G117>0,1,0)+T118 -> 39 | U117: =IF(H117>0,1,0)+U118 -> 32 | V117: =IF(I117>0,1,0)+V118 -> 35 | W117: =IF(J117>0,1,0)+W118 -> 112 | X117: =IF(K117>0,1,0)+X118 -> 104 | Y117: =IF(L117>0,1,0)+Y118 -> 46 | Z117: =IF(M117>0,1,0)+Z118 -> 33 | ... AD117: =IF(Q117>0,1,0)+AD118 -> 37 | AF117: =IF(S117<=$AT$1,F117,0) -> 0 | AG117: =IF(T117<=$AT$1,G117,0) -> 0 | AH117: =IF(U117<=$AT$1,H117,0) -> 0 | AI117: =IF(V117<=$AT$1,I117,0) -> 0 | AJ117: =IF(W117<=$AT$1,J117,0) -> 0 | AK117: =IF(X117<=$AT$1,K117,0) -> 0 | AL117: =IF(Y117<=$AT$1,L117,0) -> 0 | AM117: =IF(Z117<=$AT$1,M117,0) -> 0 | ... AQ117: =IF(AD117<=$AT$1,Q117,0) -> 0
A118: 4 | B118: 02.04.2024 | C118: MGBK-3 | D118: SPUR-06 | E118: 2790.5398 | F118: =IF(D118="SPUR-01",E118,0) -> 0 | G118: =IF(D118="SPUR-02",E118,0) -> 0 | H118: =IF(D118="SPUR-03",E118,0) -> 0 | I118: =IF(D118="SPUR-04",E118,0) -> 0 | J118: =IF(D118="SPUR-05",E118,0) -> 0 | K118: =IF(D118="SPUR-06",E118,0) -> 2790.5398 | L118: =IF(D118="SPUR-07",E118,0) -> 0 | M118: =IF(D118="SPUR-08",E118,0) -> 0 | N118: =IF(D118="SPUR-09",E118,0) -> 0 | O118: =IF(D118="SPUR-10",E118,0) -> 0 | P118: =IF(D118="SPUR-SILO",E118,0) -> 0 | Q118: =IF(D118="SPUR-DB",E118,0) -> 0 | S118: =IF(F118>0,1,0)+S119 -> 57 | T118: =IF(G118>0,1,0)+T119 -> 39 | U118: =IF(H118>0,1,0)+U119 -> 32 | V118: =IF(I118>0,1,0)+V119 -> 35 | W118: =IF(J118>0,1,0)+W119 -> 112 | X118: =IF(K118>0,1,0)+X119 -> 104 | Y118: =IF(L118>0,1,0)+Y119 -> 46 | Z118: =IF(M118>0,1,0)+Z119 -> 33 | ... AD118: =IF(Q118>0,1,0)+AD119 -> 37 | AF118: =IF(S118<=$AT$1,F118,0) -> 0 | AG118: =IF(T118<=$AT$1,G118,0) -> 0 | AH118: =IF(U118<=$AT$1,H118,0) -> 0 | AI118: =IF(V118<=$AT$1,I118,0) -> 0 | AJ118: =IF(W118<=$AT$1,J118,0) -> 0 | AK118: =IF(X118<=$AT$1,K118,0) -> 0 | AL118: =IF(Y118<=$AT$1,L118,0) -> 0 | AM118: =IF(Z118<=$AT$1,M118,0) -> 0 | ... AQ118: =IF(AD118<=$AT$1,Q118,0) -> 0
A119: 5 | B119: 02.04.2024 | C119: NMGBK-112 | D119: SPUR-SILO | E119: 3589.6331 | F119: =IF(D119="SPUR-01",E119,0) -> 0 | G119: =IF(D119="SPUR-02",E119,0) -> 0 | H119: =IF(D119="SPUR-03",E119,0) -> 0 | I119: =IF(D119="SPUR-04",E119,0) -> 0 | J119: =IF(D119="SPUR-05",E119,0) -> 0 | K119: =IF(D119="SPUR-06",E119,0) -> 0 | L119: =IF(D119="SPUR-07",E119,0) -> 0 | M119: =IF(D119="SPUR-08",E119,0) -> 0 | N119: =IF(D119="SPUR-09",E119,0) -> 0 | O119: =IF(D119="SPUR-10",E119,0) -> 0 | P119: =IF(D119="SPUR-SILO",E119,0) -> 3589.6331 | Q119: =IF(D119="SPUR-DB",E119,0) -> 0 | S119: =IF(F119>0,1,0)+S120 -> 57 | T119: =IF(G119>0,1,0)+T120 -> 39 | U119: =IF(H119>0,1,0)+U120 -> 32 | V119: =IF(I119>0,1,0)+V120 -> 35 | W119: =IF(J119>0,1,0)+W120 -> 112 | X119: =IF(K119>0,1,0)+X120 -> 103 | Y119: =IF(L119>0,1,0)+Y120 -> 46 | Z119: =IF(M119>0,1,0)+Z120 -> 33 | ... AD119: =IF(Q119>0,1,0)+AD120 -> 37 | AF119: =IF(S119<=$AT$1,F119,0) -> 0 | AG119: =IF(T119<=$AT$1,G119,0) -> 0 | AH119: =IF(U119<=$AT$1,H119,0) -> 0 | AI119: =IF(V119<=$AT$1,I119,0) -> 0 | AJ119: =IF(W119<=$AT$1,J119,0) -> 0 | AK119: =IF(X119<=$AT$1,K119,0) -> 0 | AL119: =IF(Y119<=$AT$1,L119,0) -> 0 | AM119: =IF(Z119<=$AT$1,M119,0) -> 0 | ... AQ119: =IF(AD119<=$AT$1,Q119,0) -> 0
A120: 6 | B120: 02.04.2024 | C120: MGBK-05 | D120: SPUR-07 | E120: 3102.765 | F120: =IF(D120="SPUR-01",E120,0) -> 0 | G120: =IF(D120="SPUR-02",E120,0) -> 0 | H120: =IF(D120="SPUR-03",E120,0) -> 0 | I120: =IF(D120="SPUR-04",E120,0) -> 0 | J120: =IF(D120="SPUR-05",E120,0) -> 0 | K120: =IF(D120="SPUR-06",E120,0) -> 0 | L120: =IF(D120="SPUR-07",E120,0) -> 3102.765 | M120: =IF(D120="SPUR-08",E120,0) -> 0 | N120: =IF(D120="SPUR-09",E120,0) -> 0 | O120: =IF(D120="SPUR-10",E120,0) -> 0 | P120: =IF(D120="SPUR-SILO",E120,0) -> 0 | Q120: =IF(D120="SPUR-DB",E120,0) -> 0 | S120: =IF(F120>0,1,0)+S121 -> 57 | T120: =IF(G120>0,1,0)+T121 -> 39 | U120: =IF(H120>0,1,0)+U121 -> 32 | V120: =IF(I120>0,1,0)+V121 -> 35 | W120: =IF(J120>0,1,0)+W121 -> 112 | X120: =IF(K120>0,1,0)+X121 -> 103 | Y120: =IF(L120>0,1,0)+Y121 -> 46 | Z120: =IF(M120>0,1,0)+Z121 -> 33 | ... AD120: =IF(Q120>0,1,0)+AD121 -> 37 | AF120: =IF(S120<=$AT$1,F120,0) -> 0 | AG120: =IF(T120<=$AT$1,G120,0) -> 0 | AH120: =IF(U120<=$AT$1,H120,0) -> 0 | AI120: =IF(V120<=$AT$1,I120,0) -> 0 | AJ120: =IF(W120<=$AT$1,J120,0) -> 0 | AK120: =IF(X120<=$AT$1,K120,0) -> 0 | AL120: =IF(Y120<=$AT$1,L120,0) -> 0 | AM120: =IF(Z120<=$AT$1,M120,0) -> 0 | ... AQ120: =IF(AD120<=$AT$1,Q120,0) -> 0
A121: 7 | B121: 02.04.2024 | C121: MGBK-06 | D121: SPUR-04 | E121: 3049.9415 | F121: =IF(D121="SPUR-01",E121,0) -> 0 | G121: =IF(D121="SPUR-02",E121,0) -> 0 | H121: =IF(D121="SPUR-03",E121,0) -> 0 | I121: =IF(D121="SPUR-04",E121,0) -> 3049.9415 | J121: =IF(D121="SPUR-05",E121,0) -> 0 | K121: =IF(D121="SPUR-06",E121,0) -> 0 | L121: =IF(D121="SPUR-07",E121,0) -> 0 | M121: =IF(D121="SPUR-08",E121,0) -> 0 | N121: =IF(D121="SPUR-09",E121,0) -> 0 | O121: =IF(D121="SPUR-10",E121,0) -> 0 | P121: =IF(D121="SPUR-SILO",E121,0) -> 0 | Q121: =IF(D121="SPUR-DB",E121,0) -> 0 | S121: =IF(F121>0,1,0)+S122 -> 57 | T121: =IF(G121>0,1,0)+T122 -> 39 | U121: =IF(H121>0,1,0)+U122 -> 32 | V121: =IF(I121>0,1,0)+V122 -> 35 | W121: =IF(J121>0,1,0)+W122 -> 112 | X121: =IF(K121>0,1,0)+X122 -> 103 | Y121: =IF(L121>0,1,0)+Y122 -> 45 | Z121: =IF(M121>0,1,0)+Z122 -> 33 | ... AD121: =IF(Q121>0,1,0)+AD122 -> 37 | AF121: =IF(S121<=$AT$1,F121,0) -> 0 | AG121: =IF(T121<=$AT$1,G121,0) -> 0 | AH121: =IF(U121<=$AT$1,H121,0) -> 0 | AI121: =IF(V121<=$AT$1,I121,0) -> 0 | AJ121: =IF(W121<=$AT$1,J121,0) -> 0 | AK121: =IF(X121<=$AT$1,K121,0) -> 0 | AL121: =IF(Y121<=$AT$1,L121,0) -> 0 | AM121: =IF(Z121<=$AT$1,M121,0) -> 0 | ... AQ121: =IF(AD121<=$AT$1,Q121,0) -> 0
A122: 8 | B122: 03.04.2024 | C122: MGBK-08 | D122: SPUR-03 | E122: 3073.3648 | F122: =IF(D122="SPUR-01",E122,0) -> 0 | G122: =IF(D122="SPUR-02",E122,0) -> 0 | H122: =IF(D122="SPUR-03",E122,0) -> 3073.3648 | I122: =IF(D122="SPUR-04",E122,0) -> 0 | J122: =IF(D122="SPUR-05",E122,0) -> 0 | K122: =IF(D122="SPUR-06",E122,0) -> 0 | L122: =IF(D122="SPUR-07",E122,0) -> 0 | M122: =IF(D122="SPUR-08",E122,0) -> 0 | N122: =IF(D122="SPUR-09",E122,0) -> 0 | O122: =IF(D122="SPUR-10",E122,0) -> 0 | P122: =IF(D122="SPUR-SILO",E122,0) -> 0 | Q122: =IF(D122="SPUR-DB",E122,0) -> 0 | S122: =IF(F122>0,1,0)+S123 -> 57 | T122: =IF(G122>0,1,0)+T123 -> 39 | U122: =IF(H122>0,1,0)+U123 -> 32 | V122: =IF(I122>0,1,0)+V123 -> 34 | W122: =IF(J122>0,1,0)+W123 -> 112 | X122: =IF(K122>0,1,0)+X123 -> 103 | Y122: =IF(L122>0,1,0)+Y123 -> 45 | Z122: =IF(M122>0,1,0)+Z123 -> 33 | ... AD122: =IF(Q122>0,1,0)+AD123 -> 37 | AF122: =IF(S122<=$AT$1,F122,0) -> 0 | AG122: =IF(T122<=$AT$1,G122,0) -> 0 | AH122: =IF(U122<=$AT$1,H122,0) -> 0 | AI122: =IF(V122<=$AT$1,I122,0) -> 0 | AJ122: =IF(W122<=$AT$1,J122,0) -> 0 | AK122: =IF(X122<=$AT$1,K122,0) -> 0 | AL122: =IF(Y122<=$AT$1,L122,0) -> 0 | AM122: =IF(Z122<=$AT$1,M122,0) -> 0 | ... AQ122: =IF(AD122<=$AT$1,Q122,0) -> 0
A123: 9 | B123: 03.04.2024 | C123: MGBK-07 | D123: SPUR-01 | E123: 3505.5418 | F123: =IF(D123="SPUR-01",E123,0) -> 3505.5418 | G123: =IF(D123="SPUR-02",E123,0) -> 0 | H123: =IF(D123="SPUR-03",E123,0) -> 0 | I123: =IF(D123="SPUR-04",E123,0) -> 0 | J123: =IF(D123="SPUR-05",E123,0) -> 0 | K123: =IF(D123="SPUR-06",E123,0) -> 0 | L123: =IF(D123="SPUR-07",E123,0) -> 0 | M123: =IF(D123="SPUR-08",E123,0) -> 0 | N123: =IF(D123="SPUR-09",E123,0) -> 0 | O123: =IF(D123="SPUR-10",E123,0) -> 0 | P123: =IF(D123="SPUR-SILO",E123,0) -> 0 | Q123: =IF(D123="SPUR-DB",E123,0) -> 0 | S123: =IF(F123>0,1,0)+S124 -> 57 | T123: =IF(G123>0,1,0)+T124 -> 39 | U123: =IF(H123>0,1,0)+U124 -> 31 | V123: =IF(I123>0,1,0)+V124 -> 34 | W123: =IF(J123>0,1,0)+W124 -> 112 | X123: =IF(K123>0,1,0)+X124 -> 103 | Y123: =IF(L123>0,1,0)+Y124 -> 45 | Z123: =IF(M123>0,1,0)+Z124 -> 33 | ... AD123: =IF(Q123>0,1,0)+AD124 -> 37 | AF123: =IF(S123<=$AT$1,F123,0) -> 0 | AG123: =IF(T123<=$AT$1,G123,0) -> 0 | AH123: =IF(U123<=$AT$1,H123,0) -> 0 | AI123: =IF(V123<=$AT$1,I123,0) -> 0 | AJ123: =IF(W123<=$AT$1,J123,0) -> 0 | AK123: =IF(X123<=$AT$1,K123,0) -> 0 | AL123: =IF(Y123<=$AT$1,L123,0) -> 0 | AM123: =IF(Z123<=$AT$1,M123,0) -> 0 | ... AQ123: =IF(AD123<=$AT$1,Q123,0) -> 0
A124: 10 | B124: 03.04.2024 | C124: MGBK-10 | D124: SPUR-05 | E124: 2844.1321 | F124: =IF(D124="SPUR-01",E124,0) -> 0 | G124: =IF(D124="SPUR-02",E124,0) -> 0 | H124: =IF(D124="SPUR-03",E124,0) -> 0 | I124: =IF(D124="SPUR-04",E124,0) -> 0 | J124: =IF(D124="SPUR-05",E124,0) -> 2844.1321 | K124: =IF(D124="SPUR-06",E124,0) -> 0 | L124: =IF(D124="SPUR-07",E124,0) -> 0 | M124: =IF(D124="SPUR-08",E124,0) -> 0 | N124: =IF(D124="SPUR-09",E124,0) -> 0 | O124: =IF(D124="SPUR-10",E124,0) -> 0 | P124: =IF(D124="SPUR-SILO",E124,0) -> 0 | Q124: =IF(D124="SPUR-DB",E124,0) -> 0 | S124: =IF(F124>0,1,0)+S125 -> 56 | T124: =IF(G124>0,1,0)+T125 -> 39 | U124: =IF(H124>0,1,0)+U125 -> 31 | V124: =IF(I124>0,1,0)+V125 -> 34 | W124: =IF(J124>0,1,0)+W125 -> 112 | X124: =IF(K124>0,1,0)+X125 -> 103 | Y124: =IF(L124>0,1,0)+Y125 -> 45 | Z124: =IF(M124>0,1,0)+Z125 -> 33 | ... AD124: =IF(Q124>0,1,0)+AD125 -> 37 | AF124: =IF(S124<=$AT$1,F124,0) -> 0 | AG124: =IF(T124<=$AT$1,G124,0) -> 0 | AH124: =IF(U124<=$AT$1,H124,0) -> 0 | AI124: =IF(V124<=$AT$1,I124,0) -> 0 | AJ124: =IF(W124<=$AT$1,J124,0) -> 0 | AK124: =IF(X124<=$AT$1,K124,0) -> 0 | AL124: =IF(Y124<=$AT$1,L124,0) -> 0 | AM124: =IF(Z124<=$AT$1,M124,0) -> 0 | ... AQ124: =IF(AD124<=$AT$1,Q124,0) -> 0
A125: 11 | B125: 03.04.2024 | C125: MGBK-09 | D125: SPUR-04 | E125: 3020.1978 | F125: =IF(D125="SPUR-01",E125,0) -> 0 | G125: =IF(D125="SPUR-02",E125,0) -> 0 | H125: =IF(D125="SPUR-03",E125,0) -> 0 | I125: =IF(D125="SPUR-04",E125,0) -> 3020.1978 | J125: =IF(D125="SPUR-05",E125,0) -> 0 | K125: =IF(D125="SPUR-06",E125,0) -> 0 | L125: =IF(D125="SPUR-07",E125,0) -> 0 | M125: =IF(D125="SPUR-08",E125,0) -> 0 | N125: =IF(D125="SPUR-09",E125,0) -> 0 | O125: =IF(D125="SPUR-10",E125,0) -> 0 | P125: =IF(D125="SPUR-SILO",E125,0) -> 0 | Q125: =IF(D125="SPUR-DB",E125,0) -> 0 | S125: =IF(F125>0,1,0)+S126 -> 56 | T125: =IF(G125>0,1,0)+T126 -> 39 | U125: =IF(H125>0,1,0)+U126 -> 31 | V125: =IF(I125>0,1,0)+V126 -> 34 | W125: =IF(J125>0,1,0)+W126 -> 111 | X125: =IF(K125>0,1,0)+X126 -> 103 | Y125: =IF(L125>0,1,0)+Y126 -> 45 | Z125: =IF(M125>0,1,0)+Z126 -> 33 | ... AD125: =IF(Q125>0,1,0)+AD126 -> 37 | AF125: =IF(S125<=$AT$1,F125,0) -> 0 | AG125: =IF(T125<=$AT$1,G125,0) -> 0 | AH125: =IF(U125<=$AT$1,H125,0) -> 0 | AI125: =IF(V125<=$AT$1,I125,0) -> 0 | AJ125: =IF(W125<=$AT$1,J125,0) -> 0 | AK125: =IF(X125<=$AT$1,K125,0) -> 0 | AL125: =IF(Y125<=$AT$1,L125,0) -> 0 | AM125: =IF(Z125<=$AT$1,M125,0) -> 0 | ... AQ125: =IF(AD125<=$AT$1,Q125,0) -> 0
A126: 12 | B126: 03.04.2024 | C126: MGBK-12 | D126: SPUR-03 | E126: 2715.7527 | F126: =IF(D126="SPUR-01",E126,0) -> 0 | G126: =IF(D126="SPUR-02",E126,0) -> 0 | H126: =IF(D126="SPUR-03",E126,0) -> 2715.7527 | I126: =IF(D126="SPUR-04",E126,0) -> 0 | J126: =IF(D126="SPUR-05",E126,0) -> 0 | K126: =IF(D126="SPUR-06",E126,0) -> 0 | L126: =IF(D126="SPUR-07",E126,0) -> 0 | M126: =IF(D126="SPUR-08",E126,0) -> 0 | N126: =IF(D126="SPUR-09",E126,0) -> 0 | O126: =IF(D126="SPUR-10",E126,0) -> 0 | P126: =IF(D126="SPUR-SILO",E126,0) -> 0 | Q126: =IF(D126="SPUR-DB",E126,0) -> 0 | S126: =IF(F126>0,1,0)+S127 -> 56 | T126: =IF(G126>0,1,0)+T127 -> 39 | U126: =IF(H126>0,1,0)+U127 -> 31 | V126: =IF(I126>0,1,0)+V127 -> 33 | W126: =IF(J126>0,1,0)+W127 -> 111 | X126: =IF(K126>0,1,0)+X127 -> 103 | Y126: =IF(L126>0,1,0)+Y127 -> 45 | Z126: =IF(M126>0,1,0)+Z127 -> 33 | ... AD126: =IF(Q126>0,1,0)+AD127 -> 37 | AF126: =IF(S126<=$AT$1,F126,0) -> 0 | AG126: =IF(T126<=$AT$1,G126,0) -> 0 | AH126: =IF(U126<=$AT$1,H126,0) -> 0 | AI126: =IF(V126<=$AT$1,I126,0) -> 0 | AJ126: =IF(W126<=$AT$1,J126,0) -> 0 | AK126: =IF(X126<=$AT$1,K126,0) -> 0 | AL126: =IF(Y126<=$AT$1,L126,0) -> 0 | AM126: =IF(Z126<=$AT$1,M126,0) -> 0 | ... AQ126: =IF(AD126<=$AT$1,Q126,0) -> 0
... A202: 88 | B202: 23.04.2024 | C202: NMGBK-89 | D202: SPUR-03 | E202: 2541.2251 | F202: =IF(D202="SPUR-01",E202,0) -> 0 | G202: =IF(D202="SPUR-02",E202,0) -> 0 | H202: =IF(D202="SPUR-03",E202,0) -> 2541.2251 | I202: =IF(D202="SPUR-04",E202,0) -> 0 | J202: =IF(D202="SPUR-05",E202,0) -> 0 | K202: =IF(D202="SPUR-06",E202,0) -> 0 | L202: =IF(D202="SPUR-07",E202,0) -> 0 | M202: =IF(D202="SPUR-08",E202,0) -> 0 | N202: =IF(D202="SPUR-09",E202,0) -> 0 | O202: =IF(D202="SPUR-10",E202,0) -> 0 | P202: =IF(D202="SPUR-SILO",E202,0) -> 0 | Q202: =IF(D202="SPUR-DB",E202,0) -> 0 | S202: =IF(F202>0,1,0)+S203 -> 53 | T202: =IF(G202>0,1,0)+T203 -> 38 | U202: =IF(H202>0,1,0)+U203 -> 22 | V202: =IF(I202>0,1,0)+V203 -> 23 | W202: =IF(J202>0,1,0)+W203 -> 103 | X202: =IF(K202>0,1,0)+X203 -> 93 | Y202: =IF(L202>0,1,0)+Y203 -> 36 | Z202: =IF(M202>0,1,0)+Z203 -> 30 | ... AD202: =IF(Q202>0,1,0)+AD203 -> 26 | AF202: =IF(S202<=$AT$1,F202,0) -> 0 | AG202: =IF(T202<=$AT$1,G202,0) -> 0 | AH202: =IF(U202<=$AT$1,H202,0) -> 0 | AI202: =IF(V202<=$AT$1,I202,0) -> 0 | AJ202: =IF(W202<=$AT$1,J202,0) -> 0 | AK202: =IF(X202<=$AT$1,K202,0) -> 0 | AL202: =IF(Y202<=$AT$1,L202,0) -> 0 | AM202: =IF(Z202<=$AT$1,M202,0) -> 0 | ... AQ202: =IF(AD202<=$AT$1,Q202,0) -> 0
F203: =IF(D203="SPUR-01",E203,0) -> 0 | G203: =IF(D203="SPUR-02",E203,0) -> 0 | H203: =IF(D203="SPUR-03",E203,0) -> 0 | I203: =IF(D203="SPUR-04",E203,0) -> 0 | J203: =IF(D203="SPUR-05",E203,0) -> 0 | K203: =IF(D203="SPUR-06",E203,0) -> 0 | L203: =IF(D203="SPUR-07",E203,0) -> 0 | M203: =IF(D203="SPUR-08",E203,0) -> 0 | N203: =IF(D203="SPUR-09",E203,0) -> 0 | O203: =IF(D203="SPUR-10",E203,0) -> 0 | P203: =IF(D203="SPUR-SILO",E203,0) -> 0 | Q203: =IF(D203="SPUR-DB",E203,0) -> 0 | S203: =IF(F203>0,1,0)+S204 -> 53 | T203: =IF(G203>0,1,0)+T204 -> 38 | U203: =IF(H203>0,1,0)+U204 -> 21 | V203: =IF(I203>0,1,0)+V204 -> 23 | W203: =IF(J203>0,1,0)+W204 -> 103 | X203: =IF(K203>0,1,0)+X204 -> 93 | Y203: =IF(L203>0,1,0)+Y204 -> 36 | Z203: =IF(M203>0,1,0)+Z204 -> 30 | ... AD203: =IF(Q203>0,1,0)+AD204 -> 26 | AF203: =IF(S203<=$AT$1,F203,0) -> 0 | AG203: =IF(T203<=$AT$1,G203,0) -> 0 | AH203: =IF(U203<=$AT$1,H203,0) -> 0 | AI203: =IF(V203<=$AT$1,I203,0) -> 0 | AJ203: =IF(W203<=$AT$1,J203,0) -> 0 | AK203: =IF(X203<=$AT$1,K203,0) -> 0 | AL203: =IF(Y203<=$AT$1,L203,0) -> 0 | AM203: =IF(Z203<=$AT$1,M203,0) -> 0 | ... AQ203: =IF(AD203<=$AT$1,Q203,0) -> 0
A204: 1 | B204: 01.05.2024 | C204: MGBK-2 | D204: SPUR-5 | E204: 3021.6587 | F204: =IF(D204="SPUR-01",E204,0) -> 0 | G204: =IF(D204="SPUR-02",E204,0) -> 0 | H204: =IF(D204="SPUR-03",E204,0) -> 0 | I204: =IF(D204="SPUR-04",E204,0) -> 0 | J204: =IF(D204="SPUR-05",E204,0) -> 0 | K204: =IF(D204="SPUR-06",E204,0) -> 0 | L204: =IF(D204="SPUR-07",E204,0) -> 0 | M204: =IF(D204="SPUR-08",E204,0) -> 0 | N204: =IF(D204="SPUR-09",E204,0) -> 0 | O204: =IF(D204="SPUR-10",E204,0) -> 0 | P204: =IF(D204="SPUR-SILO",E204,0) -> 0 | Q204: =IF(D204="SPUR-DB",E204,0) -> 0 | S204: =IF(F204>0,1,0)+S205 -> 53 | T204: =IF(G204>0,1,0)+T205 -> 38 | U204: =IF(H204>0,1,0)+U205 -> 21 | V204: =IF(I204>0,1,0)+V205 -> 23 | W204: =IF(J204>0,1,0)+W205 -> 103 | X204: =IF(K204>0,1,0)+X205 -> 93 | Y204: =IF(L204>0,1,0)+Y205 -> 36 | Z204: =IF(M204>0,1,0)+Z205 -> 30 | ... AD204: =IF(Q204>0,1,0)+AD205 -> 26 | AF204: =IF(S204<=$AT$1,F204,0) -> 0 | AG204: =IF(T204<=$AT$1,G204,0) -> 0 | AH204: =IF(U204<=$AT$1,H204,0) -> 0 | AI204: =IF(V204<=$AT$1,I204,0) -> 0 | AJ204: =IF(W204<=$AT$1,J204,0) -> 0 | AK204: =IF(X204<=$AT$1,K204,0) -> 0 | AL204: =IF(Y204<=$AT$1,L204,0) -> 0 | AM204: =IF(Z204<=$AT$1,M204,0) -> 0 | ... AQ204: =IF(AD204<=$AT$1,Q204,0) -> 0
A205: 2 | B205: 01.05.2024 | C205: MGBK-4 | D205: LSST-SILO | E205: 3042.3492 | F205: =IF(D205="SPUR-01",E205,0) -> 0 | G205: =IF(D205="SPUR-02",E205,0) -> 0 | H205: =IF(D205="SPUR-03",E205,0) -> 0 | I205: =IF(D205="SPUR-04",E205,0) -> 0 | J205: =IF(D205="SPUR-05",E205,0) -> 0 | K205: =IF(D205="SPUR-06",E205,0) -> 0 | L205: =IF(D205="SPUR-07",E205,0) -> 0 | M205: =IF(D205="SPUR-08",E205,0) -> 0 | N205: =IF(D205="SPUR-09",E205,0) -> 0 | O205: =IF(D205="SPUR-10",E205,0) -> 0 | P205: =IF(D205="SPUR-SILO",E205,0) -> 0 | Q205: =IF(D205="SPUR-DB",E205,0) -> 0 | S205: =IF(F205>0,1,0)+S206 -> 53 | T205: =IF(G205>0,1,0)+T206 -> 38 | U205: =IF(H205>0,1,0)+U206 -> 21 | V205: =IF(I205>0,1,0)+V206 -> 23 | W205: =IF(J205>0,1,0)+W206 -> 103 | X205: =IF(K205>0,1,0)+X206 -> 93 | Y205: =IF(L205>0,1,0)+Y206 -> 36 | Z205: =IF(M205>0,1,0)+Z206 -> 30 | ... AD205: =IF(Q205>0,1,0)+AD206 -> 26 | AF205: =IF(S205<=$AT$1,F205,0) -> 0 | AG205: =IF(T205<=$AT$1,G205,0) -> 0 | AH205: =IF(U205<=$AT$1,H205,0) -> 0 | AI205: =IF(V205<=$AT$1,I205,0) -> 0 | AJ205: =IF(W205<=$AT$1,J205,0) -> 0 | AK205: =IF(X205<=$AT$1,K205,0) -> 0 | AL205: =IF(Y205<=$AT$1,L205,0) -> 0 | AM205: =IF(Z205<=$AT$1,M205,0) -> 0 | ... AQ205: =IF(AD205<=$AT$1,Q205,0) -> 0
A206: 3 | B206: 01.05.2024 | C206: MGBK-1 | D206: SPUR-8 | E206: 3101.143 | F206: =IF(D206="SPUR-01",E206,0) -> 0 | G206: =IF(D206="SPUR-02",E206,0) -> 0 | H206: =IF(D206="SPUR-03",E206,0) -> 0 | I206: =IF(D206="SPUR-04",E206,0) -> 0 | J206: =IF(D206="SPUR-05",E206,0) -> 0 | K206: =IF(D206="SPUR-06",E206,0) -> 0 | L206: =IF(D206="SPUR-07",E206,0) -> 0 | M206: =IF(D206="SPUR-08",E206,0) -> 0 | N206: =IF(D206="SPUR-09",E206,0) -> 0 | O206: =IF(D206="SPUR-10",E206,0) -> 0 | P206: =IF(D206="SPUR-SILO",E206,0) -> 0 | Q206: =IF(D206="SPUR-DB",E206,0) -> 0 | S206: =IF(F206>0,1,0)+S207 -> 53 | T206: =IF(G206>0,1,0)+T207 -> 38 | U206: =IF(H206>0,1,0)+U207 -> 21 | V206: =IF(I206>0,1,0)+V207 -> 23 | W206: =IF(J206>0,1,0)+W207 -> 103 | X206: =IF(K206>0,1,0)+X207 -> 93 | Y206: =IF(L206>0,1,0)+Y207 -> 36 | Z206: =IF(M206>0,1,0)+Z207 -> 30 | ... AD206: =IF(Q206>0,1,0)+AD207 -> 26 | AF206: =IF(S206<=$AT$1,F206,0) -> 0 | AG206: =IF(T206<=$AT$1,G206,0) -> 0 | AH206: =IF(U206<=$AT$1,H206,0) -> 0 | AI206: =IF(V206<=$AT$1,I206,0) -> 0 | AJ206: =IF(W206<=$AT$1,J206,0) -> 0 | AK206: =IF(X206<=$AT$1,K206,0) -> 0 | AL206: =IF(Y206<=$AT$1,L206,0) -> 0 | AM206: =IF(Z206<=$AT$1,M206,0) -> 0 | ... AQ206: =IF(AD206<=$AT$1,Q206,0) -> 0
A207: 4 | B207: 02.05.2024 | C207: NMGBK-3 | D207: SPUR-6 | E207: 3243.742 | F207: =IF(D207="SPUR-01",E207,0) -> 0 | G207: =IF(D207="SPUR-02",E207,0) -> 0 | H207: =IF(D207="SPUR-03",E207,0) -> 0 | I207: =IF(D207="SPUR-04",E207,0) -> 0 | J207: =IF(D207="SPUR-05",E207,0) -> 0 | K207: =IF(D207="SPUR-06",E207,0) -> 0 | L207: =IF(D207="SPUR-07",E207,0) -> 0 | M207: =IF(D207="SPUR-08",E207,0) -> 0 | N207: =IF(D207="SPUR-09",E207,0) -> 0 | O207: =IF(D207="SPUR-10",E207,0) -> 0 | P207: =IF(D207="SPUR-SILO",E207,0) -> 0 | Q207: =IF(D207="SPUR-DB",E207,0) -> 0 | S207: =IF(F207>0,1,0)+S208 -> 53 | T207: =IF(G207>0,1,0)+T208 -> 38 | U207: =IF(H207>0,1,0)+U208 -> 21 | V207: =IF(I207>0,1,0)+V208 -> 23 | W207: =IF(J207>0,1,0)+W208 -> 103 | X207: =IF(K207>0,1,0)+X208 -> 93 | Y207: =IF(L207>0,1,0)+Y208 -> 36 | Z207: =IF(M207>0,1,0)+Z208 -> 30 | ... AD207: =IF(Q207>0,1,0)+AD208 -> 26 | AF207: =IF(S207<=$AT$1,F207,0) -> 0 | AG207: =IF(T207<=$AT$1,G207,0) -> 0 | AH207: =IF(U207<=$AT$1,H207,0) -> 0 | AI207: =IF(V207<=$AT$1,I207,0) -> 0 | AJ207: =IF(W207<=$AT$1,J207,0) -> 0 | AK207: =IF(X207<=$AT$1,K207,0) -> 0 | AL207: =IF(Y207<=$AT$1,L207,0) -> 0 | AM207: =IF(Z207<=$AT$1,M207,0) -> 0 | ... AQ207: =IF(AD207<=$AT$1,Q207,0) -> 0
A208: 5 | B208: 02.05.2024 | C208: MGBK-5 | D208: LSST-SILO | E208: 3316.4172 | F208: =IF(D208="SPUR-01",E208,0) -> 0 | G208: =IF(D208="SPUR-02",E208,0) -> 0 | H208: =IF(D208="SPUR-03",E208,0) -> 0 | I208: =IF(D208="SPUR-04",E208,0) -> 0 | J208: =IF(D208="SPUR-05",E208,0) -> 0 | K208: =IF(D208="SPUR-06",E208,0) -> 0 | L208: =IF(D208="SPUR-07",E208,0) -> 0 | M208: =IF(D208="SPUR-08",E208,0) -> 0 | N208: =IF(D208="SPUR-09",E208,0) -> 0 | O208: =IF(D208="SPUR-10",E208,0) -> 0 | P208: =IF(D208="SPUR-SILO",E208,0) -> 0 | Q208: =IF(D208="SPUR-DB",E208,0) -> 0 | S208: =IF(F208>0,1,0)+S209 -> 53 | T208: =IF(G208>0,1,0)+T209 -> 38 | U208: =IF(H208>0,1,0)+U209 -> 21 | V208: =IF(I208>0,1,0)+V209 -> 23 | W208: =IF(J208>0,1,0)+W209 -> 103 | X208: =IF(K208>0,1,0)+X209 -> 93 | Y208: =IF(L208>0,1,0)+Y209 -> 36 | Z208: =IF(M208>0,1,0)+Z209 -> 30 | ... AD208: =IF(Q208>0,1,0)+AD209 -> 26 | AF208: =IF(S208<=$AT$1,F208,0) -> 0 | AG208: =IF(T208<=$AT$1,G208,0) -> 0 | AH208: =IF(U208<=$AT$1,H208,0) -> 0 | AI208: =IF(V208<=$AT$1,I208,0) -> 0 | AJ208: =IF(W208<=$AT$1,J208,0) -> 0 | AK208: =IF(X208<=$AT$1,K208,0) -> 0 | AL208: =IF(Y208<=$AT$1,L208,0) -> 0 | AM208: =IF(Z208<=$AT$1,M208,0) -> 0 | ... AQ208: =IF(AD208<=$AT$1,Q208,0) -> 0
A209: 6 | B209: 02.05.2024 | C209: MGBK-7 | D209: SPUR-6 | E209: 3052.5194 | F209: =IF(D209="SPUR-01",E209,0) -> 0 | G209: =IF(D209="SPUR-02",E209,0) -> 0 | H209: =IF(D209="SPUR-03",E209,0) -> 0 | I209: =IF(D209="SPUR-04",E209,0) -> 0 | J209: =IF(D209="SPUR-05",E209,0) -> 0 | K209: =IF(D209="SPUR-06",E209,0) -> 0 | L209: =IF(D209="SPUR-07",E209,0) -> 0 | M209: =IF(D209="SPUR-08",E209,0) -> 0 | N209: =IF(D209="SPUR-09",E209,0) -> 0 | O209: =IF(D209="SPUR-10",E209,0) -> 0 | P209: =IF(D209="SPUR-SILO",E209,0) -> 0 | Q209: =IF(D209="SPUR-DB",E209,0) -> 0 | S209: =IF(F209>0,1,0)+S210 -> 53 | T209: =IF(G209>0,1,0)+T210 -> 38 | U209: =IF(H209>0,1,0)+U210 -> 21 | V209: =IF(I209>0,1,0)+V210 -> 23 | W209: =IF(J209>0,1,0)+W210 -> 103 | X209: =IF(K209>0,1,0)+X210 -> 93 | Y209: =IF(L209>0,1,0)+Y210 -> 36 | Z209: =IF(M209>0,1,0)+Z210 -> 30 | ... AD209: =IF(Q209>0,1,0)+AD210 -> 26 | AF209: =IF(S209<=$AT$1,F209,0) -> 0 | AG209: =IF(T209<=$AT$1,G209,0) -> 0 | AH209: =IF(U209<=$AT$1,H209,0) -> 0 | AI209: =IF(V209<=$AT$1,I209,0) -> 0 | AJ209: =IF(W209<=$AT$1,J209,0) -> 0 | AK209: =IF(X209<=$AT$1,K209,0) -> 0 | AL209: =IF(Y209<=$AT$1,L209,0) -> 0 | AM209: =IF(Z209<=$AT$1,M209,0) -> 0 | ... AQ209: =IF(AD209<=$AT$1,Q209,0) -> 0
A210: 7 | B210: 03.05.2024 | C210: MGBK-06 | D210: SPUR-8 | E210: 3577.8483 | F210: =IF(D210="SPUR-01",E210,0) -> 0 | G210: =IF(D210="SPUR-02",E210,0) -> 0 | H210: =IF(D210="SPUR-03",E210,0) -> 0 | I210: =IF(D210="SPUR-04",E210,0) -> 0 | J210: =IF(D210="SPUR-05",E210,0) -> 0 | K210: =IF(D210="SPUR-06",E210,0) -> 0 | L210: =IF(D210="SPUR-07",E210,0) -> 0 | M210: =IF(D210="SPUR-08",E210,0) -> 0 | N210: =IF(D210="SPUR-09",E210,0) -> 0 | O210: =IF(D210="SPUR-10",E210,0) -> 0 | P210: =IF(D210="SPUR-SILO",E210,0) -> 0 | Q210: =IF(D210="SPUR-DB",E210,0) -> 0 | S210: =IF(F210>0,1,0)+S211 -> 53 | T210: =IF(G210>0,1,0)+T211 -> 38 | U210: =IF(H210>0,1,0)+U211 -> 21 | V210: =IF(I210>0,1,0)+V211 -> 23 | W210: =IF(J210>0,1,0)+W211 -> 103 | X210: =IF(K210>0,1,0)+X211 -> 93 | Y210: =IF(L210>0,1,0)+Y211 -> 36 | Z210: =IF(M210>0,1,0)+Z211 -> 30 | ... AD210: =IF(Q210>0,1,0)+AD211 -> 26 | AF210: =IF(S210<=$AT$1,F210,0) -> 0 | AG210: =IF(T210<=$AT$1,G210,0) -> 0 | AH210: =IF(U210<=$AT$1,H210,0) -> 0 | AI210: =IF(V210<=$AT$1,I210,0) -> 0 | AJ210: =IF(W210<=$AT$1,J210,0) -> 0 | AK210: =IF(X210<=$AT$1,K210,0) -> 0 | AL210: =IF(Y210<=$AT$1,L210,0) -> 0 | AM210: =IF(Z210<=$AT$1,M210,0) -> 0 | ... AQ210: =IF(AD210<=$AT$1,Q210,0) -> 0
A211: 8 | B211: 03.05.2024 | C211: MGBK-10 | D211: SPUR-5 | E211: 3264.1049 | F211: =IF(D211="SPUR-01",E211,0) -> 0 | G211: =IF(D211="SPUR-02",E211,0) -> 0 | H211: =IF(D211="SPUR-03",E211,0) -> 0 | I211: =IF(D211="SPUR-04",E211,0) -> 0 | J211: =IF(D211="SPUR-05",E211,0) -> 0 | K211: =IF(D211="SPUR-06",E211,0) -> 0 | L211: =IF(D211="SPUR-07",E211,0) -> 0 | M211: =IF(D211="SPUR-08",E211,0) -> 0 | N211: =IF(D211="SPUR-09",E211,0) -> 0 | O211: =IF(D211="SPUR-10",E211,0) -> 0 | P211: =IF(D211="SPUR-SILO",E211,0) -> 0 | Q211: =IF(D211="SPUR-DB",E211,0) -> 0 | S211: =IF(F211>0,1,0)+S212 -> 53 | T211: =IF(G211>0,1,0)+T212 -> 38 | U211: =IF(H211>0,1,0)+U212 -> 21 | V211: =IF(I211>0,1,0)+V212 -> 23 | W211: =IF(J211>0,1,0)+W212 -> 103 | X211: =IF(K211>0,1,0)+X212 -> 93 | Y211: =IF(L211>0,1,0)+Y212 -> 36 | Z211: =IF(M211>0,1,0)+Z212 -> 30 | ... AD211: =IF(Q211>0,1,0)+AD212 -> 26 | AF211: =IF(S211<=$AT$1,F211,0) -> 0 | AG211: =IF(T211<=$AT$1,G211,0) -> 0 | AH211: =IF(U211<=$AT$1,H211,0) -> 0 | AI211: =IF(V211<=$AT$1,I211,0) -> 0 | AJ211: =IF(W211<=$AT$1,J211,0) -> 0 | AK211: =IF(X211<=$AT$1,K211,0) -> 0 | AL211: =IF(Y211<=$AT$1,L211,0) -> 0 | AM211: =IF(Z211<=$AT$1,M211,0) -> 0 | ... AQ211: =IF(AD211<=$AT$1,Q211,0) -> 0
A212: 9 | B212: 03.05.2024 | C212: MGBK-08 | D212: SPUR-7 | E212: 3250.7892 | F212: =IF(D212="SPUR-01",E212,0) -> 0 | G212: =IF(D212="SPUR-02",E212,0) -> 0 | H212: =IF(D212="SPUR-03",E212,0) -> 0 | I212: =IF(D212="SPUR-04",E212,0) -> 0 | J212: =IF(D212="SPUR-05",E212,0) -> 0 | K212: =IF(D212="SPUR-06",E212,0) -> 0 | L212: =IF(D212="SPUR-07",E212,0) -> 0 | M212: =IF(D212="SPUR-08",E212,0) -> 0 | N212: =IF(D212="SPUR-09",E212,0) -> 0 | O212: =IF(D212="SPUR-10",E212,0) -> 0 | P212: =IF(D212="SPUR-SILO",E212,0) -> 0 | Q212: =IF(D212="SPUR-DB",E212,0) -> 0 | S212: =IF(F212>0,1,0)+S213 -> 53 | T212: =IF(G212>0,1,0)+T213 -> 38 | U212: =IF(H212>0,1,0)+U213 -> 21 | V212: =IF(I212>0,1,0)+V213 -> 23 | W212: =IF(J212>0,1,0)+W213 -> 103 | X212: =IF(K212>0,1,0)+X213 -> 93 | Y212: =IF(L212>0,1,0)+Y213 -> 36 | Z212: =IF(M212>0,1,0)+Z213 -> 30 | ... AD212: =IF(Q212>0,1,0)+AD213 -> 26 | AF212: =IF(S212<=$AT$1,F212,0) -> 0 | AG212: =IF(T212<=$AT$1,G212,0) -> 0 | AH212: =IF(U212<=$AT$1,H212,0) -> 0 | AI212: =IF(V212<=$AT$1,I212,0) -> 0 | AJ212: =IF(W212<=$AT$1,J212,0) -> 0 | AK212: =IF(X212<=$AT$1,K212,0) -> 0 | AL212: =IF(Y212<=$AT$1,L212,0) -> 0 | AM212: =IF(Z212<=$AT$1,M212,0) -> 0 | ... AQ212: =IF(AD212<=$AT$1,Q212,0) -> 0
